Workbook

Sheet Start Here
B2: Basket: Produce & Recipe Library
B3: Nigerian-market produce catalogue, seasonal calendar and a recipe library of stews & sauces, breakfast plates, salads & cooked sides, fruit plates & desserts, and bowls & snacks, each scored for Basket coverage and vitamins. Version 2, 24 Oct 2026. Drinks, smoothies, juices and soups removed.
B5: Settings
B6: Basket coverage target | C6: 0.8 | D6: Share of a recipe's non-staple ingredients that should come from Basket. Set at 80% from the positioning brief. Change it and every recipe re-scores.
B8: Daily values used for the '% daily' columns
B9: Nutrient | C9: Daily value | D9: Source / note
B10: Fibre (g) | C10: 25 | D10: WHO / EFSA adult guidance of 25 g a day.
B11: Vitamin C (mg) | C11: 80 | D11: EU nutrient reference value (Reg. 1169/2011). US uses 90 mg.
B12: Vitamin A (mcg) | C12: 800 | D12: EU NRV, micrograms retinol activity equivalent. Beta-carotene in carrot, pawpaw and mango is converted at the USDA RAE rate.
B13: Vitamin K (mcg) | C13: 75 | D13: EU NRV. Leafy greens (ugu, efo, kale, spinach) dominate this column.
B14: Folate (mcg) | C14: 200 | D14: EU NRV. US uses 400 mcg DFE; pregnancy guidance is higher.
B15: Potassium (mg) | C15: 2000 | D15: EU NRV. WHO suggests 3,510 mg for adults; change here if you prefer the WHO figure.
B16: Vitamin E (mg) | C16: 12 | D16: EU NRV. Avocado, groundnut and leafy greens are the main produce sources.
B17: Vitamin B6 (mg) | C17: 1.4 | D17: EU NRV. Banana, avocado, sweet potato and garlic contribute most.
B18: Magnesium (mg) | C18: 375 | D18: EU NRV.
B19: Iron (mg) | C19: 14 | D19: EU NRV. Plant iron from greens absorbs better eaten with vitamin C (tomato, tatashe, citrus), which is why stews pair the two.
B21: At a glance
B22: Produce items catalogued | C22: =COUNTA(Produce!A2:A500) -> 84
B23: Recipes | C23: =COUNTA(Recipes!A2:A500) -> 156
B24: Stews & Sauces | C24: =COUNTIF(Recipes!C2:C500,"Stews & Sauces") -> 32
B25: Breakfast Plates | C25: =COUNTIF(Recipes!C2:C500,"Breakfast Plates") -> 24
B26: Salads & Cooked Sides | C26: =COUNTIF(Recipes!C2:C500,"Salads & Cooked Sides") -> 42
B27: Fruit Plates & Desserts | C27: =COUNTIF(Recipes!C2:C500,"Fruit Plates & Desserts") -> 24
B28: Bowls & Snacks | C28: =COUNTIF(Recipes!C2:C500,"Bowls & Snacks") -> 34
B29: Recipes hitting the coverage target | C29: =COUNTIF(Recipes!AX2:AX500,"Yes") -> 60
B30: Average Basket coverage | C30: =AVERAGE(Recipes!AW2:AW500) -> 0.73825651
B31: Recipes giving 50%+ of daily vitamin C | C31: =COUNTIF(Recipes!AG2:AG500,">=0.5") -> 92
B32: Recipes giving 50%+ of daily vitamin A | C32: =COUNTIF(Recipes!AH2:AH500,">=0.5") -> 28
B33: Recipes with a reference image | C33: =COUNTIF(Recipes!I2:I500,"http*") -> 140
B34: Produce in season this month | C34: =COUNTIF(Produce!J2:J500,"Peak")+COUNTIF(Produce!J2:J500,"In") -> 69
B35: Vegan / plant-based recipes | C35: =COUNTIF(Recipes!M2:M500,"Vegan") -> 74
B36: No-cook recipes | C36: =COUNTIF(Recipes!Q2:Q500,"No-cook") -> 45
B38: What's in each tab
B39: Produce | C39: Every fruit, vegetable, herb and nut worth stocking: local names, season, role, sell unit, benchmark price, storage, launch tier, and how many recipes use it.
B40: Seasonal Calendar | C40: Month-by-month availability. The Produce tab reads this to show what is in season today.
B41: Nutrition | C41: Per-100 g vitamins and minerals for every produce item (USDA / FAO), plus typical piece and cup weights. Recipe nutrition is computed from this.
B42: Recipes | C42: The library. Five categories, the global dish each is based on, source page and reference image, what changed for Lagos, what the customer adds (rice, protein, bread), timings, kcal, vitamins per serving, % of daily values, an auto-generated health tagline, the other nutrients above 25% of a day, method and Basket coverage.
B43: Recipe Ingredients | C43: One row per ingredient with quantity, unit, source (Basket / Protein / Pantry / Staple) and an estimated gram weight. Coverage scores and vitamins are built from this table.
B44: Box Ideas | C44: Seasonal drops and themed baskets, each linked to the recipes it unlocks.
B45: Market Scan | C45: What the Lagos players and the international meal kits do, what to borrow, and the gap Basket can own.
...

Sheet Produce
A1: ID | B1: Produce | C1: Local names | D1: Category | E1: Origin | F1: Role | G1: Availability | H1: Season | I1: Peak | J1: In season now? | K1: Season confidence | L1: Sell unit | M1: Benchmark price (N) | N1: Benchmark unit | O1: Benchmark source | P1: Basket price (N) | Q1: Stock it? | R1: Launch tier | S1: Used in # recipes | T1: Storage | U1: Shelf life | V1: Sourcing region | W1: Best for | X1: Notes
A2: P001 | B2: Banana | C2: Ogede wewe (Yor), Ayaba (Hau) | D2: Fruit | E2: Local | F2: Eat as-is + recipes | G2: Year-round | H2: All year | J2: =IFERROR(IF(INDEX('Seasonal Calendar'!$C$2:$N$500,MATCH(A2,'Seasonal Calendar'!$A$2:$A$500,0),MONTH(TODAY()))="","Out",INDEX('Seasonal Calendar'!$C$2:$N$500,MATCH(A2,'Seasonal Calendar'!$A$2:$A$500,0),MONTH(TODAY()))),"") -> In | K2: Verify | L2: Hand (~1kg) | M2: 1850 | N2: 1kg | O2: The Fresh Place (thefreshplace.ng), 11 Oct 2026 | Q2: Y | R2: Core | S2: =COUNTIF('Recipe Ingredients'!$F$2:$F$2000,A2) -> 8 | T2: Room temp; fridge once fully ripe (skin darkens, flesh holds) | U2: 3-5 days | V2: Ondo, Ogun, Cross River, Edo | W2: Training, Energy | X2: Most-used fruit in the recipe library. Sell spotty, very ripe bananas as discounted 'smoothie bananas' rather than writing them off.
A3: P002 | B3: Plantain (ripe & unripe) | C3: Ogede agbagba (Yor), Agade (Hau) | D3: Fruit (cooking) | E3: Local | F3: Recipe ingredient | G3: Year-round | H3: All year | J3: =IFERROR(IF(INDEX('Seasonal Calendar'!$C$2:$N$500,MATCH(A3,'Seasonal Calendar'!$A$2:$A$500,0),MONTH(TODAY()))="","Out",INDEX('Seasonal Calendar'!$C$2:$N$500,MATCH(A3,'Seasonal Calendar'!$A$2:$A$500,0),MONTH(TODAY()))),"") -> In | K3: Verify | L3: Finger / bunch | Q3: Y | R3: Core | S3: =COUNTIF('Recipe Ingredients'!$F$2:$F$2000,A3) -> 2 | T3: Room temp; ripens in 3-6 days | U3: 5-10 days | V3: Ondo, Edo, Ogun, Cross River | W3: Training, Energy | X3: Sell by ripeness stage (green, yellow, black-spotted) so recipes get the right one.
A4: P003 | B4: Pineapple | C4: Ope oyinbo (Yor), Abarba (Hau) | D4: Fruit | E4: Local | F4: Eat as-is + recipes | G4: Year-round | H4: All year | J4: =IFERROR(IF(INDEX('Seasonal Calendar'!$C$2:$N$500,MATCH(A4,'Seasonal Calendar'!$A$2:$A$500,0),MONTH(TODAY()))="","Out",INDEX('Seasonal Calendar'!$C$2:$N$500,MATCH(A4,'Seasonal Calendar'!$A$2:$A$500,0),MONTH(TODAY()))),"") -> In | K4: Verify | L4: Piece | M4: 1300 | N4: 1 pc | O4: Mint Foods (mintfoods.store), 11 Oct 2026; Bendel pineapple N3,000/pc at The Fresh Place (thefreshplace.ng), 11 Oct 2026 | Q4: Y | R4: Core | S4: =COUNTIF('Recipe Ingredients'!$F$2:$F$2000,A4) -> 13 | T4: Room temp until fragrant; fridge once cut | U4: 3-5 days whole, 3 days cut | V4: Edo (Bendel), Ogun, Oyo, Delta | W4: Hydration, Wellness | X4: Bendel and sugarloaf types are sweeter than imported. Price gap between sellers is wide (N1,300 vs N3,000).
A5: P004 | B5: Watermelon | C5: Bara (Yor), Kankana (Hau) | D5: Fruit | E5: Local | F5: Eat as-is + recipes | G5: Year-round | H5: All year | I5: Dec-Apr | J5: =IFERROR(IF(INDEX('Seasonal Calendar'!$C$2:$N$500,MATCH(A5,'Seasonal Calendar'!$A$2:$A$500,0),MONTH(TODAY()))="","Out",INDEX('Seasonal Calendar'!$C$2:$N$500,MATCH(A5,'Seasonal Calendar'!$A$2:$A$500,0),MONTH(TODAY()))),"") -> In | K5: Verify | L5: Piece (S/M/L) or half | Q5: Y | R5: Core | S5: =COUNTIF('Recipe Ingredients'!$F$2:$F$2000,A5) -> 4 | T5: Whole at room temp; cut in fridge, wrapped | U5: 1-2 weeks whole, 3 days cut | V5: Kano, Kaduna, Jigawa, Plateau | W5: Hydration, Weight management | X5: Listed by Kitchen Butterfly as available all year; northern supply heaviest in the dry season.
A6: P005 | B6: Pawpaw (papaya) | C6: Ibepe (Yor), Gwanda (Hau) | D6: Fruit | E6: Local | F6: Eat as-is + recipes | G6: Year-round | H6: All year | J6: =IFERROR(IF(INDEX('Seasonal Calendar'!$C$2:$N$500,MATCH(A6,'Seasonal Calendar'!$A$2:$A$500,0),MONTH(TODAY()))="","Out",INDEX('Seasonal Calendar'!$C$2:$N$500,MATCH(A6,'Seasonal Calendar'!$A$2:$A$500,0),MONTH(TODAY()))),"") -> In | K6: Verify | L6: Piece | Q6: Y | R6: Core | S6: =COUNTIF('Recipe Ingredients'!$F$2:$F$2000,A6) -> 9 | T6: Ripen at room temp; fridge when soft | U6: 2-4 days ripe | V6: Nationwide | W6: Gut health, Weight management | X6: Unripe (green) pawpaw is a recipe ingredient too (green papaya salad).
A7: P006 | B7: Mango | C7: Mangoro (Yor/Hau) | D7: Fruit | E7: Local | F7: Eat as-is + recipes | G7: Seasonal | H7: Feb-May, Aug-Sep | I7: Mar-Apr | J7: =IFERROR(IF(INDEX('Seasonal Calendar'!$C$2:$N$500,MATCH(A7,'Seasonal Calendar'!$A$2:$A$500,0),MONTH(TODAY()))="","Out",INDEX('Seasonal Calendar'!$C$2:$N$500,MATCH(A7,'Seasonal Calendar'!$A$2:$A$500,0),MONTH(TODAY()))),"") -> Out | K7: Sourced | L7: Piece / 1kg | M7: 500 | N7: 1 pc (cherry mango) | O7: The Fresh Place (thefreshplace.ng), 11 Oct 2026 | Q7: Seasonal | R7: Seasonal drop | S7: =COUNTIF('Recipe Ingredients'!$F$2:$F$2000,A7) -> 15 | T7: Room temp to ripen; fridge when ripe | U7: 3-5 days ripe | V7: Oyo (Ogbomoso), Benue, Kaduna, Niger | W7: Energy, Wellness | X7: Main season Feb-May with a smaller Aug-Sep run. Varieties worth naming on the app: Ogbomoso, Julie, cherry, 'German'.
A8: P007 | B8: Orange | C8: Osan (Yor), Oroma (Igbo), Lemu (Hau) | D8: Fruit (citrus) | E8: Local + imported | F8: Eat as-is + recipes | G8: Year-round | H8: All year | I8: Oct-Jan | J8: =IFERROR(IF(INDEX('Seasonal Calendar'!$C$2:$N$500,MATCH(A8,'Seasonal Calendar'!$A$2:$A$500,0),MONTH(TODAY()))="","Out",INDEX('Seasonal Calendar'!$C$2:$N$500,MATCH(A8,'Seasonal Calendar'!$A$2:$A$500,0),MONTH(TODAY()))),"") -> Peak | K8: Sourced | L8: Piece / dozen | M8: 950 | N8: 1 pc imported | O8: The Fresh Place (thefreshplace.ng), 11 Oct 2026; South African 5 pcs N4,750 at Mint Foods (mintfoods.store), 11 Oct 2026 | Q8: Y | R8: Core | S8: =COUNTIF('Recipe Ingredients'!$F$2:$F$2000,A8) -> 7 | T8: Room temp 1 week; fridge 2-3 weeks | U8: 1-3 weeks | V8: Benue (citrus belt), Ogun, Oyo | W8: Wellness, Hydration | X8: Available all year with varying quality; best fruit Oct-Dec per Kitchen Butterfly.
A9: P008 | B9: Tangerine | D9: Fruit (citrus) | E9: Local + imported | F9: Eat as-is + recipes | G9: Year-round | H9: All year | I9: Oct-Jan | J9: =IFERROR(IF(INDEX('Seasonal Calendar'!$C$2:$N$500,MATCH(A9,'Seasonal Calendar'!$A$2:$A$500,0),MONTH(TODAY()))="","Out",INDEX('Seasonal Calendar'!$C$2:$N$500,MATCH(A9,'Seasonal Calendar'!$A$2:$A$500,0),MONTH(TODAY()))),"") -> Peak | K9: Sourced | L9: Piece | M9: 300 | N9: 1 pc local | O9: The Fresh Place (thefreshplace.ng), 11 Oct 2026; imported clementine N850 | Q9: Y | R9: Core | S9: =COUNTIF('Recipe Ingredients'!$F$2:$F$2000,A9) -> 2 | T9: Room temp 1 week; fridge 2 weeks | U9: 1-2 weeks | V9: Benue, Ogun | W9: Wellness | X9: Local vs imported price is nearly 3x.
A10: P009 | B10: Lemon | D10: Fruit (citrus) | E10: Local + imported | F10: Recipe ingredient | G10: Year-round | H10: All year | I10: Oct-Jan | J10: =IFERROR(IF(INDEX('Seasonal Calendar'!$C$2:$N$500,MATCH(A10,'Seasonal Calendar'!$A$2:$A$500,0),MONTH(TODAY()))="","Out",INDEX('Seasonal Calendar'!$C$2:$N$500,MATCH(A10,'Seasonal Calendar'!$A$2:$A$500,0),MONTH(TODAY()))),"") -> Peak | K10: Verify | L10: Piece | M10: 300 | N10: 1 pc local | O10: The Fresh Place (thefreshplace.ng), 11 Oct 2026; imported N950/pc; Mint Foods (mintfoods.store), 11 Oct 2026: 4 local N1,900 vs 5 Dutch N13,800 | Q10: Y | R10: Core | S10: =COUNTIF('Recipe Ingredients'!$F$2:$F$2000,A10) -> 33 | T10: Fridge | U10: 2-3 weeks | V10: Benue, Plateau | W10: Wellness | X10: Used in more recipes than almost anything else. Strong case for local-only.
A11: P010 | B11: Lime | C11: Osan wewe (Yor) | D11: Fruit (citrus) | E11: Local | F11: Recipe ingredient | G11: Year-round | H11: All year | I11: Oct-Jan | J11: =IFERROR(IF(INDEX('Seasonal Calendar'!$C$2:$N$500,MATCH(A11,'Seasonal Calendar'!$A$2:$A$500,0),MONTH(TODAY()))="","Out",INDEX('Seasonal Calendar'!$C$2:$N$500,MATCH(A11,'Seasonal Calendar'!$A$2:$A$500,0),MONTH(TODAY()))),"") -> Peak | K11: Sourced | L11: Piece / pack of 4 | Q11: Y | R11: Core | S11: =COUNTIF('Recipe Ingredients'!$F$2:$F$2000,A11) -> 59 | T11: Fridge | U11: 2-3 weeks | V11: Benue, Ogun, Oyo | W11: Wellness | X11: Best fruit Oct-Dec (Kitchen Butterfly). Workhorse acid for salsas, dressings and drinks.
A12: P011 | B12: Grapefruit | D12: Fruit (citrus) | E12: Local | F12: Eat as-is + recipes | G12: Year-round | H12: All year | I12: Oct-Jan | J12: =IFERROR(IF(INDEX('Seasonal Calendar'!$C$2:$N$500,MATCH(A12,'Seasonal Calendar'!$A$2:$A$500,0),MONTH(TODAY()))="","Out",INDEX('Seasonal Calendar'!$C$2:$N$500,MATCH(A12,'Seasonal Calendar'!$A$2:$A$500,0),MONTH(TODAY()))),"") -> Peak | K12: Verify | L12: Piece | Q12: N | R12: Later | S12: =COUNTIF('Recipe Ingredients'!$F$2:$F$2000,A12) -> 2 | T12: Room temp / fridge | U12: 2-3 weeks | V12: Benue | W12: Weight management | X12: Niche but cheap locally. Good add-on for citrus boxes.
A13: P012 | B13: Avocado | C13: Pia (Yor) | D13: Fruit | E13: Local + imported | F13: Eat as-is + recipes | G13: Year-round | H13: All year | J13: =IFERROR(IF(INDEX('Seasonal Calendar'!$C$2:$N$500,MATCH(A13,'Seasonal Calendar'!$A$2:$A$500,0),MONTH(TODAY()))="","Out",INDEX('Seasonal Calendar'!$C$2:$N$500,MATCH(A13,'Seasonal Calendar'!$A$2:$A$500,0),MONTH(TODAY()))),"") -> In | K13: Verify | L13: Piece | M13: 2000 | N13: 1 pc medium | O13: The Fresh Place (thefreshplace.ng), 11 Oct 2026; big N2,500; Mint Foods (mintfoods.store), 11 Oct 2026: local N1,050, imported 2-pack N7,300 | Q13: Y | R13: Core | S13: =COUNTIF('Recipe Ingredients'!$F$2:$F$2000,A13) -> 16 | T13: Room temp to ripen; fridge once ripe | U13: 2-3 days ripe | V13: Southwest, Cross River, Plateau | W13: Training, Wellness | X13: Local supply and quality swing through the year. Confirm local peak months with suppliers. Mint sells a ready-to-eat 'eat me' pack, worth copying.
A14: P013 | B14: Guava | C14: Gova (Yor), Gwaba (Hau) | D14: Fruit | E14: Local + imported | F14: Eat as-is + recipes | G14: Seasonal | H14: Feb-Mar, Aug-Sep | I14: Feb-Mar | J14: =IFERROR(IF(INDEX('Seasonal Calendar'!$C$2:$N$500,MATCH(A14,'Seasonal Calendar'!$A$2:$A$500,0),MONTH(TODAY()))="","Out",INDEX('Seasonal Calendar'!$C$2:$N$500,MATCH(A14,'Seasonal Calendar'!$A$2:$A$500,0),MONTH(TODAY()))),"") -> Out | K14: Sourced | L14: Piece / 1kg | M14: 16000 | N14: 1kg imported | O14: The Fresh Place (thefreshplace.ng), 11 Oct 2026 | Q14: Seasonal | R14: Seasonal drop | S14: =COUNTIF('Recipe Ingredients'!$F$2:$F$2000,A14) -> 2 | T14: Room temp; fridge when soft | U14: 3-4 days | V14: Nationwide | W14: Wellness | X14: Two short local windows. Imported guava sells at a premium.
A15: P014 | B15: Soursop | D15: Fruit | E15: Local | F15: Eat as-is + recipes | G15: Seasonal | H15: Dec-Mar, May-Aug, Oct | I15: Feb-Mar | J15: =IFERROR(IF(INDEX('Seasonal Calendar'!$C$2:$N$500,MATCH(A15,'Seasonal Calendar'!$A$2:$A$500,0),MONTH(TODAY()))="","Out",INDEX('Seasonal Calendar'!$C$2:$N$500,MATCH(A15,'Seasonal Calendar'!$A$2:$A$500,0),MONTH(TODAY()))),"") -> In | K15: Sourced | L15: Piece / 1kg | M15: 5500 | N15: 1kg | O15: The Fresh Place (thefreshplace.ng), 11 Oct 2026 | Q15: Seasonal | R15: Seasonal drop | S15: =COUNTIF('Recipe Ingredients'!$F$2:$F$2000,A15) -> 0 | T15: Room temp until soft; fridge after | U15: 2-3 days ripe | V15: Southwest, South-south | W15: Wellness | X15: Seeds must be removed before blending.
A16: P015 | B16: Passion fruit | D16: Fruit | E16: Local + imported | F16: Recipe ingredient | G16: Seasonal | H16: Jan-Mar, May-Jun, Aug-Nov | J16: =IFERROR(IF(INDEX('Seasonal Calendar'!$C$2:$N$500,MATCH(A16,'Seasonal Calendar'!$A$2:$A$500,0),MONTH(TODAY()))="","Out",INDEX('Seasonal Calendar'!$C$2:$N$500,MATCH(A16,'Seasonal Calendar'!$A$2:$A$500,0),MONTH(TODAY()))),"") -> In | K16: Sourced | L16: Pack of 4 | M16: 7280 | N16: 4 pcs imported | O16: Mint Foods (mintfoods.store), 11 Oct 2026; imported 1kg N40,000 at The Fresh Place (thefreshplace.ng), 11 Oct 2026 | Q16: N | R16: Premium | S16: =COUNTIF('Recipe Ingredients'!$F$2:$F$2000,A16) -> 3 | T16: Room temp; fridge when wrinkled | U16: 1-2 weeks | V16: Plateau | W16: Wellness | X16: Local supply exists (Plateau). Imported is very expensive, so source locally.
A17: P016 | B17: Coconut | C17: Agbon (Yor), Kwakwa (Hau) | D17: Fruit | E17: Local | F17: Eat as-is + recipes | G17: Year-round | H17: All year | J17: =IFERROR(IF(INDEX('Seasonal Calendar'!$C$2:$N$500,MATCH(A17,'Seasonal Calendar'!$A$2:$A$500,0),MONTH(TODAY()))="","Out",INDEX('Seasonal Calendar'!$C$2:$N$500,MATCH(A17,'Seasonal Calendar'!$A$2:$A$500,0),MONTH(TODAY()))),"") -> In | K17: Verify | L17: Piece | M17: 1300 | N17: 1 dry coconut | O17: Mint Foods (mintfoods.store), 11 Oct 2026 | Q17: Y | R17: Core | S17: =COUNTIF('Recipe Ingredients'!$F$2:$F$2000,A17) -> 14 | T17: Room temp | U17: 2-3 weeks whole | V17: Lagos (Badagry), Ogun, Ondo coast | W17: Plant-based, Hydration | X17: Fresh coconut milk replaces canned in most recipes here.
A18: P017 | B18: Agbalumo (African star apple) | C18: Agbalumo (Yor), Udara (Igbo), 'cherry' (Lagos) | D18: Fruit | E18: Local | F18: Eat as-is only | G18: Seasonal | H18: Dec-May | I18: Jan-Mar | J18: =IFERROR(IF(INDEX('Seasonal Calendar'!$C$2:$N$500,MATCH(A18,'Seasonal Calendar'!$A$2:$A$500,0),MONTH(TODAY()))="","Out",INDEX('Seasonal Calendar'!$C$2:$N$500,MATCH(A18,'Seasonal Calendar'!$A$2:$A$500,0),MONTH(TODAY()))),"") -> Out | K18: Sourced | L18: Pack of 10 / 20 | Q18: Seasonal | R18: Seasonal drop | S18: =COUNTIF('Recipe Ingredients'!$F$2:$F$2000,A18) -> 0 | T18: Room temp | U18: 3-5 days | V18: Southwest and Southeast forest zones | W18: Wellness | X18: Hero of the seasonal drop calendar. Wild-harvested, so grade by size and sell by count.
A19: P018 | B19: Cashew apple | C19: Kaju (Yor), Kanju (Hau) | D19: Fruit | E19: Local | F19: Eat as-is only | G19: Seasonal | H19: Feb-Mar | I19: Feb-Mar | J19: =IFERROR(IF(INDEX('Seasonal Calendar'!$C$2:$N$500,MATCH(A19,'Seasonal Calendar'!$A$2:$A$500,0),MONTH(TODAY()))="","Out",INDEX('Seasonal Calendar'!$C$2:$N$500,MATCH(A19,'Seasonal Calendar'!$A$2:$A$500,0),MONTH(TODAY()))),"") -> Out | K19: Sourced | L19: Pack | Q19: N | R19: Later | S19: =COUNTIF('Recipe Ingredients'!$F$2:$F$2000,A19) -> 0 | T19: Fridge; bruises fast | U19: 1-2 days | V19: Kogi, Oyo, Enugu | W19: Wellness | X19: Very short shelf life. Test only.
A20: P019 | B20: Velvet tamarind | C20: Awin (Yor), Icheku (Igbo), Tsamiyar kurmi (Hau) | D20: Fruit | E20: Local | F20: Eat as-is only | G20: Seasonal | H20: Jan-May | I20: Feb-Mar | J20: =IFERROR(IF(INDEX('Seasonal Calendar'!$C$2:$N$500,MATCH(A20,'Seasonal Calendar'!$A$2:$A$500,0),MONTH(TODAY()))="","Out",INDEX('Seasonal Calendar'!$C$2:$N$500,MATCH(A20,'Seasonal Calendar'!$A$2:$A$500,0),MONTH(TODAY()))),"") -> Out | K20: Sourced | L20: Cup / 100g pack | Q20: Seasonal | R20: Seasonal drop | S20: =COUNTIF('Recipe Ingredients'!$F$2:$F$2000,A20) -> 0 | T20: Dry, airtight | U20: Weeks | V20: Southwest, Southeast, North | W20: Snack | X20: Shelf-stable and nostalgic. Natural checkout add-on.
A21: P020 | B21: Hog plum | C21: Iyeye (Yor) | D21: Fruit | E21: Local | F21: Eat as-is only | G21: Seasonal | H21: Jul, Dec | I21: Jul | J21: =IFERROR(IF(INDEX('Seasonal Calendar'!$C$2:$N$500,MATCH(A21,'Seasonal Calendar'!$A$2:$A$500,0),MONTH(TODAY()))="","Out",INDEX('Seasonal Calendar'!$C$2:$N$500,MATCH(A21,'Seasonal Calendar'!$A$2:$A$500,0),MONTH(TODAY()))),"") -> Out | K21: Sourced | L21: Pack | Q21: N | R21: Later | S21: =COUNTIF('Recipe Ingredients'!$F$2:$F$2000,A21) -> 0 | T21: Fridge | U21: 1-2 days | V21: Southwest | W21: Snack | X21: Very short season and shelf life.
A22: P021 | B22: Pepper fruit | C22: Mmimi (Igbo) | D22: Fruit | E22: Local | F22: Eat as-is only | G22: Seasonal | H22: Feb-May | J22: =IFERROR(IF(INDEX('Seasonal Calendar'!$C$2:$N$500,MATCH(A22,'Seasonal Calendar'!$A$2:$A$500,0),MONTH(TODAY()))="","Out",INDEX('Seasonal Calendar'!$C$2:$N$500,MATCH(A22,'Seasonal Calendar'!$A$2:$A$500,0),MONTH(TODAY()))),"") -> Out | K22: Sourced | L22: Cup | Q22: N | R22: Later | S22: =COUNTIF('Recipe Ingredients'!$F$2:$F$2000,A22) -> 0 | T22: Room temp | U22: 3-5 days | V22: Southeast | W22: Snack
A23: P022 | B23: Monkey kola | C23: Ochicha (Igbo), Obi edun (Yor) | D23: Fruit | E23: Local | F23: Eat as-is only | G23: Seasonal | H23: May-Aug | J23: =IFERROR(IF(INDEX('Seasonal Calendar'!$C$2:$N$500,MATCH(A23,'Seasonal Calendar'!$A$2:$A$500,0),MONTH(TODAY()))="","Out",INDEX('Seasonal Calendar'!$C$2:$N$500,MATCH(A23,'Seasonal Calendar'!$A$2:$A$500,0),MONTH(TODAY()))),"") -> Out | K23: Sourced | L23: Pack | Q23: N | R23: Later | S23: =COUNTIF('Recipe Ingredients'!$F$2:$F$2000,A23) -> 0 | T23: Room temp | U23: 3-5 days | V23: Southeast, Southwest | W23: Snack
A24: P023 | B24: African pear | C24: Ube (Igbo) | D24: Fruit | E24: Local | F24: Eat as-is only | G24: Seasonal | H24: May-Sep | I24: Jun-Aug | J24: =IFERROR(IF(INDEX('Seasonal Calendar'!$C$2:$N$500,MATCH(A24,'Seasonal Calendar'!$A$2:$A$500,0),MONTH(TODAY()))="","Out",INDEX('Seasonal Calendar'!$C$2:$N$500,MATCH(A24,'Seasonal Calendar'!$A$2:$A$500,0),MONTH(TODAY()))),"") -> Out | K24: Sourced | L24: Pack of 10 | Q24: Seasonal | R24: Seasonal drop | S24: =COUNTIF('Recipe Ingredients'!$F$2:$F$2000,A24) -> 0 | T24: Room temp | U24: 2-3 days | V24: Southeast, South-south | W24: Snack | X24: Classic pairing with roasted corn. Bundle the two as a rainy season drop.
A25: P024 | B25: Tiger nut | C25: Ofio (Yor), Aki Hausa (Igbo), Aya (Hau) | D25: Nut / tuber | E25: Local | F25: Eat as-is + recipes | G25: Seasonal | H25: Nov-May, Jul-Sep | J25: =IFERROR(IF(INDEX('Seasonal Calendar'!$C$2:$N$500,MATCH(A25,'Seasonal Calendar'!$A$2:$A$500,0),MONTH(TODAY()))="","Out",INDEX('Seasonal Calendar'!$C$2:$N$500,MATCH(A25,'Seasonal Calendar'!$A$2:$A$500,0),MONTH(TODAY()))),"") -> Out | K25: Sourced | L25: Cup / 250g | Q25: Y | R25: Core | S25: =COUNTIF('Recipe Ingredients'!$F$2:$F$2000,A25) -> 3 | T25: Dry, airtight | U25: Weeks dried | V25: Kano, Kaduna, Niger | W25: Plant-based, Gut health | X25: Snack on its own or blend into kunun aya / horchata.
A26: P025 | B26: Sugarcane | C26: Ireke (Yor), Okpete (Igbo), Rake (Hau) | D26: Fruit (cane) | E26: Local | F26: Eat as-is only | G26: Seasonal | H26: Aug-Mar | J26: =IFERROR(IF(INDEX('Seasonal Calendar'!$C$2:$N$500,MATCH(A26,'Seasonal Calendar'!$A$2:$A$500,0),MONTH(TODAY()))="","Out",INDEX('Seasonal Calendar'!$C$2:$N$500,MATCH(A26,'Seasonal Calendar'!$A$2:$A$500,0),MONTH(TODAY()))),"") -> In | K26: Sourced | L26: Stick / pre-cut pack | Q26: Seasonal | R26: Seasonal drop | S26: =COUNTIF('Recipe Ingredients'!$F$2:$F$2000,A26) -> 0 | T26: Room temp; cut pieces in fridge | U26: 3-5 days | V26: North, Southwest | W26: Snack | X26: Pre-cut, peeled pieces are the only realistic delivery format.
A27: P026 | B27: Custard apple (sweetsop) | D27: Fruit | E27: Local | F27: Eat as-is only | G27: Seasonal | H27: Feb, Aug-Sep | J27: =IFERROR(IF(INDEX('Seasonal Calendar'!$C$2:$N$500,MATCH(A27,'Seasonal Calendar'!$A$2:$A$500,0),MONTH(TODAY()))="","Out",INDEX('Seasonal Calendar'!$C$2:$N$500,MATCH(A27,'Seasonal Calendar'!$A$2:$A$500,0),MONTH(TODAY()))),"") -> Out | K27: Sourced | L27: Piece | Q27: N | R27: Later | S27: =COUNTIF('Recipe Ingredients'!$F$2:$F$2000,A27) -> 0 | T27: Room temp until soft | U27: 1-2 days ripe | V27: Southwest | W27: Snack
A28: P027 | B28: Jackfruit | D28: Fruit | E28: Local | F28: Eat as-is + recipes | G28: Seasonal | H28: May-Jun | I28: May | J28: =IFERROR(IF(INDEX('Seasonal Calendar'!$C$2:$N$500,MATCH(A28,'Seasonal Calendar'!$A$2:$A$500,0),MONTH(TODAY()))="","Out",INDEX('Seasonal Calendar'!$C$2:$N$500,MATCH(A28,'Seasonal Calendar'!$A$2:$A$500,0),MONTH(TODAY()))),"") -> Out | K28: Sourced | L28: Pre-cut pods | Q28: N | R28: Later | S28: =COUNTIF('Recipe Ingredients'!$F$2:$F$2000,A28) -> 0 | T28: Fridge once cut | U28: 2-3 days cut | V28: South | W28: Snack | X28: Sell as cleaned pods, never whole.
A29: P028 | B29: June plum | D29: Fruit | E29: Local | F29: Eat as-is only | G29: Seasonal | H29: Dec-Jan | J29: =IFERROR(IF(INDEX('Seasonal Calendar'!$C$2:$N$500,MATCH(A29,'Seasonal Calendar'!$A$2:$A$500,0),MONTH(TODAY()))="","Out",INDEX('Seasonal Calendar'!$C$2:$N$500,MATCH(A29,'Seasonal Calendar'!$A$2:$A$500,0),MONTH(TODAY()))),"") -> Out | K29: Sourced | L29: Pack | Q29: N | R29: Later | S29: =COUNTIF('Recipe Ingredients'!$F$2:$F$2000,A29) -> 0 | T29: Room temp | U29: 3-5 days | V29: South | W29: Snack
A30: P029 | B30: Sweet melon (golden / cantaloupe) | D30: Fruit | E30: Local + imported | F30: Eat as-is + recipes | G30: Year-round | H30: All year | I30: Jan, May-Jun | J30: =IFERROR(IF(INDEX('Seasonal Calendar'!$C$2:$N$500,MATCH(A30,'Seasonal Calendar'!$A$2:$A$500,0),MONTH(TODAY()))="","Out",INDEX('Seasonal Calendar'!$C$2:$N$500,MATCH(A30,'Seasonal Calendar'!$A$2:$A$500,0),MONTH(TODAY()))),"") -> In | K30: Sourced | L30: Piece | M30: 15950 | N30: 1 imported galia | O30: Mint Foods (mintfoods.store), 11 Oct 2026 | Q30: N | R30: Premium | S30: =COUNTIF('Recipe Ingredients'!$F$2:$F$2000,A30) -> 2 | T30: Room temp to ripen; fridge cut | U30: 3-5 days ripe | V30: North | W30: Hydration | X30: Local golden melon in Jan and May-Jun; imported the rest of the year at a high price.
A31: P030 | B31: Dates | C31: Dabino (Hau) | D31: Fruit | E31: Local + imported | F31: Eat as-is + recipes | G31: Year-round | H31: All year | I31: Apr-Jul | J31: =IFERROR(IF(INDEX('Seasonal Calendar'!$C$2:$N$500,MATCH(A31,'Seasonal Calendar'!$A$2:$A$500,0),MONTH(TODAY()))="","Out",INDEX('Seasonal Calendar'!$C$2:$N$500,MATCH(A31,'Seasonal Calendar'!$A$2:$A$500,0),MONTH(TODAY()))),"") -> In | K31: Sourced | L31: 250g pack | Q31: Y | R31: Core | S31: =COUNTIF('Recipe Ingredients'!$F$2:$F$2000,A31) -> 6 | T31: Airtight, cool | U31: Months dried | V31: North (Borno, Yobe) + imports | W31: Training, Energy | X31: Fresh dates Apr-Jul; dried all year. Used as the natural sweetener across the library.
A32: P031 | B32: Apple (red & green) | D32: Fruit | E32: Imported | F32: Eat as-is + recipes | G32: Year-round | H32: All year | J32: =IFERROR(IF(INDEX('Seasonal Calendar'!$C$2:$N$500,MATCH(A32,'Seasonal Calendar'!$A$2:$A$500,0),MONTH(TODAY()))="","Out",INDEX('Seasonal Calendar'!$C$2:$N$500,MATCH(A32,'Seasonal Calendar'!$A$2:$A$500,0),MONTH(TODAY()))),"") -> In | K32: Verify | L32: Piece / 6-pack | M32: 500 | N32: 1 pc small | O32: The Fresh Place (thefreshplace.ng), 11 Oct 2026; Mint Foods (mintfoods.store), 11 Oct 2026 6 red N4,200, 6 green N5,000 | Q32: Y | R32: Core (imported) | S32: =COUNTIF('Recipe Ingredients'!$F$2:$F$2000,A32) -> 5 | T32: Fridge | U32: 2-4 weeks | V32: Imported (South Africa, EU) | W32: Weight management | X32: Imported, but a basket expectation in Lagos. Every competitor bundle includes it.
A33: P032 | B33: Pear | D33: Fruit | E33: Imported | F33: Eat as-is + recipes | G33: Year-round | H33: All year | J33: =IFERROR(IF(INDEX('Seasonal Calendar'!$C$2:$N$500,MATCH(A33,'Seasonal Calendar'!$A$2:$A$500,0),MONTH(TODAY()))="","Out",INDEX('Seasonal Calendar'!$C$2:$N$500,MATCH(A33,'Seasonal Calendar'!$A$2:$A$500,0),MONTH(TODAY()))),"") -> In | K33: Verify | L33: Piece | Q33: N | R33: Premium | S33: =COUNTIF('Recipe Ingredients'!$F$2:$F$2000,A33) -> 1 | T33: Fridge once ripe | U33: 1-2 weeks | V33: Imported | W33: Weight management | X33: Included in The Fresh Place bundles (10 English pears).
A34: P033 | B34: Grapes (red / black seedless) | D34: Fruit | E34: Imported | F34: Eat as-is + recipes | G34: Year-round | H34: All year | J34: =IFERROR(IF(INDEX('Seasonal Calendar'!$C$2:$N$500,MATCH(A34,'Seasonal Calendar'!$A$2:$A$500,0),MONTH(TODAY()))="","Out",INDEX('Seasonal Calendar'!$C$2:$N$500,MATCH(A34,'Seasonal Calendar'!$A$2:$A$500,0),MONTH(TODAY()))),"") -> In | K34: Verify | L34: 500g | M34: 7500 | N34: 500g | O34: Mint Foods (mintfoods.store), 11 Oct 2026; The Fresh Place (thefreshplace.ng), 11 Oct 2026 N7,500 | Q34: N | R34: Premium | S34: =COUNTIF('Recipe Ingredients'!$F$2:$F$2000,A34) -> 5 | T34: Fridge, unwashed | U34: 5-7 days | V34: Imported | W34: Snack
A35: P034 | B35: Strawberry | D35: Fruit (berry) | E35: Local + imported | F35: Eat as-is + recipes | G35: Seasonal | H35: Nov-Apr | I35: Dec-Feb | J35: =IFERROR(IF(INDEX('Seasonal Calendar'!$C$2:$N$500,MATCH(A35,'Seasonal Calendar'!$A$2:$A$500,0),MONTH(TODAY()))="","Out",INDEX('Seasonal Calendar'!$C$2:$N$500,MATCH(A35,'Seasonal Calendar'!$A$2:$A$500,0),MONTH(TODAY()))),"") -> Out | K35: Verify | L35: 250g punnet | M35: 4550 | N35: 250g Ethiopian | O35: Mint Foods (mintfoods.store), 11 Oct 2026; Dutch 400g N17,500 | Q35: N | R35: Premium | S35: =COUNTIF('Recipe Ingredients'!$F$2:$F$2000,A35) -> 7 | T35: Fridge, unwashed | U35: 2-4 days | V35: Plateau (Jos) + imports | W35: Wellness | X35: Jos strawberries are a real local story. Season window needs supplier confirmation.
A36: P035 | B36: Blueberry | D36: Fruit (berry) | E36: Imported | F36: Eat as-is + recipes | G36: Year-round | H36: All year | J36: =IFERROR(IF(INDEX('Seasonal Calendar'!$C$2:$N$500,MATCH(A36,'Seasonal Calendar'!$A$2:$A$500,0),MONTH(TODAY()))="","Out",INDEX('Seasonal Calendar'!$C$2:$N$500,MATCH(A36,'Seasonal Calendar'!$A$2:$A$500,0),MONTH(TODAY()))),"") -> In | K36: Verify | L36: 125g | M36: 5720 | N36: 125g | O36: Mint Foods (mintfoods.store), 11 Oct 2026; The Fresh Place (thefreshplace.ng), 11 Oct 2026 N6,000 | Q36: N | R36: Premium | S36: =COUNTIF('Recipe Ingredients'!$F$2:$F$2000,A36) -> 1 | T36: Fridge | U36: 5-7 days | V36: Imported | W36: Wellness
A37: P036 | B37: Kiwi | D37: Fruit | E37: Imported | F37: Eat as-is + recipes | G37: Year-round | H37: All year | J37: =IFERROR(IF(INDEX('Seasonal Calendar'!$C$2:$N$500,MATCH(A37,'Seasonal Calendar'!$A$2:$A$500,0),MONTH(TODAY()))="","Out",INDEX('Seasonal Calendar'!$C$2:$N$500,MATCH(A37,'Seasonal Calendar'!$A$2:$A$500,0),MONTH(TODAY()))),"") -> In | K37: Verify | L37: 3-pack | M37: 3450 | N37: 3 pcs | O37: Mint Foods (mintfoods.store), 11 Oct 2026 | Q37: N | R37: Premium | S37: =COUNTIF('Recipe Ingredients'!$F$2:$F$2000,A37) -> 4 | T37: Fridge | U37: 1-2 weeks | V37: Imported | W37: Wellness
A38: P037 | B38: Pomegranate | D38: Fruit | E38: Imported | F38: Eat as-is + recipes | G38: Year-round | H38: All year | J38: =IFERROR(IF(INDEX('Seasonal Calendar'!$C$2:$N$500,MATCH(A38,'Seasonal Calendar'!$A$2:$A$500,0),MONTH(TODAY()))="","Out",INDEX('Seasonal Calendar'!$C$2:$N$500,MATCH(A38,'Seasonal Calendar'!$A$2:$A$500,0),MONTH(TODAY()))),"") -> In | K38: Verify | L38: Piece | Q38: N | R38: Later | S38: =COUNTIF('Recipe Ingredients'!$F$2:$F$2000,A38) -> 1 | T38: Fridge | U38: 2-3 weeks | V38: Imported | W38: Wellness
A39: P038 | B39: Dragon fruit | D39: Fruit | E39: Local (limited) + imported | F39: Eat as-is + recipes | G39: Year-round | H39: All year | J39: =IFERROR(IF(INDEX('Seasonal Calendar'!$C$2:$N$500,MATCH(A39,'Seasonal Calendar'!$A$2:$A$500,0),MONTH(TODAY()))="","Out",INDEX('Seasonal Calendar'!$C$2:$N$500,MATCH(A39,'Seasonal Calendar'!$A$2:$A$500,0),MONTH(TODAY()))),"") -> In | K39: Verify | L39: Piece | M39: 40000 | N39: 1kg | O39: The Fresh Place (thefreshplace.ng), 11 Oct 2026 | Q39: N | R39: Later | S39: =COUNTIF('Recipe Ingredients'!$F$2:$F$2000,A39) -> 0 | T39: Fridge | U39: 5-7 days | V39: A few local farms + imports | W39: Wellness | X39: Price makes it a showpiece, not a staple.
A40: P039 | B40: Star fruit (carambola) | D40: Fruit | E40: Local | F40: Eat as-is + recipes | G40: Year-round | H40: All year | J40: =IFERROR(IF(INDEX('Seasonal Calendar'!$C$2:$N$500,MATCH(A40,'Seasonal Calendar'!$A$2:$A$500,0),MONTH(TODAY()))="","Out",INDEX('Seasonal Calendar'!$C$2:$N$500,MATCH(A40,'Seasonal Calendar'!$A$2:$A$500,0),MONTH(TODAY()))),"") -> In | K40: Verify | L40: Piece | Q40: N | R40: Later | S40: =COUNTIF('Recipe Ingredients'!$F$2:$F$2000,A40) -> 0 | T40: Room temp / fridge | U40: 3-5 days | V40: South | W40: Snack | X40: Availability is patchy. Verify with suppliers.
...

Sheet Seasonal Calendar
A1: ID | B1: Produce | C1: Jan | D1: Feb | E1: Mar | F1: Apr | G1: May | H1: Jun | I1: Jul | J1: Aug | K1: Sep | L1: Oct | M1: Nov | N1: Dec | O1: Months available | P1: Role
A2: P001 | B2: Banana | C2: In | D2: In | E2: In | F2: In | G2: In | H2: In | I2: In | J2: In | K2: In | L2: In | M2: In | N2: In | O2: =COUNTIF(C2:N2,"Peak")+COUNTIF(C2:N2,"In") -> 12 | P2: Eat as-is + recipes
A3: P002 | B3: Plantain (ripe & unripe) | C3: In | D3: In | E3: In | F3: In | G3: In | H3: In | I3: In | J3: In | K3: In | L3: In | M3: In | N3: In | O3: =COUNTIF(C3:N3,"Peak")+COUNTIF(C3:N3,"In") -> 12 | P3: Recipe ingredient
A4: P003 | B4: Pineapple | C4: In | D4: In | E4: In | F4: In | G4: In | H4: In | I4: In | J4: In | K4: In | L4: In | M4: In | N4: In | O4: =COUNTIF(C4:N4,"Peak")+COUNTIF(C4:N4,"In") -> 12 | P4: Eat as-is + recipes
A5: P004 | B5: Watermelon | C5: Peak | D5: Peak | E5: Peak | F5: Peak | G5: In | H5: In | I5: In | J5: In | K5: In | L5: In | M5: In | N5: Peak | O5: =COUNTIF(C5:N5,"Peak")+COUNTIF(C5:N5,"In") -> 12 | P5: Eat as-is + recipes
A6: P005 | B6: Pawpaw (papaya) | C6: In | D6: In | E6: In | F6: In | G6: In | H6: In | I6: In | J6: In | K6: In | L6: In | M6: In | N6: In | O6: =COUNTIF(C6:N6,"Peak")+COUNTIF(C6:N6,"In") -> 12 | P6: Eat as-is + recipes
A7: P006 | B7: Mango | D7: In | E7: Peak | F7: Peak | G7: In | J7: In | K7: In | O7: =COUNTIF(C7:N7,"Peak")+COUNTIF(C7:N7,"In") -> 6 | P7: Eat as-is + recipes
A8: P007 | B8: Orange | C8: Peak | D8: In | E8: In | F8: In | G8: In | H8: In | I8: In | J8: In | K8: In | L8: Peak | M8: Peak | N8: Peak | O8: =COUNTIF(C8:N8,"Peak")+COUNTIF(C8:N8,"In") -> 12 | P8: Eat as-is + recipes
A9: P008 | B9: Tangerine | C9: Peak | D9: In | E9: In | F9: In | G9: In | H9: In | I9: In | J9: In | K9: In | L9: Peak | M9: Peak | N9: Peak | O9: =COUNTIF(C9:N9,"Peak")+COUNTIF(C9:N9,"In") -> 12 | P9: Eat as-is + recipes
A10: P009 | B10: Lemon | C10: Peak | D10: In | E10: In | F10: In | G10: In | H10: In | I10: In | J10: In | K10: In | L10: Peak | M10: Peak | N10: Peak | O10: =COUNTIF(C10:N10,"Peak")+COUNTIF(C10:N10,"In") -> 12 | P10: Recipe ingredient
A11: P010 | B11: Lime | C11: Peak | D11: In | E11: In | F11: In | G11: In | H11: In | I11: In | J11: In | K11: In | L11: Peak | M11: Peak | N11: Peak | O11: =COUNTIF(C11:N11,"Peak")+COUNTIF(C11:N11,"In") -> 12 | P11: Recipe ingredient
A12: P011 | B12: Grapefruit | C12: Peak | D12: In | E12: In | F12: In | G12: In | H12: In | I12: In | J12: In | K12: In | L12: Peak | M12: Peak | N12: Peak | O12: =COUNTIF(C12:N12,"Peak")+COUNTIF(C12:N12,"In") -> 12 | P12: Eat as-is + recipes
A13: P012 | B13: Avocado | C13: In | D13: In | E13: In | F13: In | G13: In | H13: In | I13: In | J13: In | K13: In | L13: In | M13: In | N13: In | O13: =COUNTIF(C13:N13,"Peak")+COUNTIF(C13:N13,"In") -> 12 | P13: Eat as-is + recipes
A14: P013 | B14: Guava | D14: Peak | E14: Peak | J14: In | K14: In | O14: =COUNTIF(C14:N14,"Peak")+COUNTIF(C14:N14,"In") -> 4 | P14: Eat as-is + recipes
A15: P014 | B15: Soursop | C15: In | D15: Peak | E15: Peak | G15: In | H15: In | I15: In | J15: In | L15: In | N15: In | O15: =COUNTIF(C15:N15,"Peak")+COUNTIF(C15:N15,"In") -> 9 | P15: Eat as-is + recipes
A16: P015 | B16: Passion fruit | C16: In | D16: In | E16: In | G16: In | H16: In | J16: In | K16: In | L16: In | M16: In | O16: =COUNTIF(C16:N16,"Peak")+COUNTIF(C16:N16,"In") -> 9 | P16: Recipe ingredient
A17: P016 | B17: Coconut | C17: In | D17: In | E17: In | F17: In | G17: In | H17: In | I17: In | J17: In | K17: In | L17: In | M17: In | N17: In | O17: =COUNTIF(C17:N17,"Peak")+COUNTIF(C17:N17,"In") -> 12 | P17: Eat as-is + recipes
A18: P017 | B18: Agbalumo (African star apple) | C18: Peak | D18: Peak | E18: Peak | F18: In | G18: In | N18: In | O18: =COUNTIF(C18:N18,"Peak")+COUNTIF(C18:N18,"In") -> 6 | P18: Eat as-is only
A19: P018 | B19: Cashew apple | D19: Peak | E19: Peak | O19: =COUNTIF(C19:N19,"Peak")+COUNTIF(C19:N19,"In") -> 2 | P19: Eat as-is only
A20: P019 | B20: Velvet tamarind | C20: In | D20: Peak | E20: Peak | F20: In | G20: In | O20: =COUNTIF(C20:N20,"Peak")+COUNTIF(C20:N20,"In") -> 5 | P20: Eat as-is only
A21: P020 | B21: Hog plum | I21: Peak | N21: In | O21: =COUNTIF(C21:N21,"Peak")+COUNTIF(C21:N21,"In") -> 2 | P21: Eat as-is only
A22: P021 | B22: Pepper fruit | D22: In | E22: In | F22: In | G22: In | O22: =COUNTIF(C22:N22,"Peak")+COUNTIF(C22:N22,"In") -> 4 | P22: Eat as-is only
A23: P022 | B23: Monkey kola | G23: In | H23: In | I23: In | J23: In | O23: =COUNTIF(C23:N23,"Peak")+COUNTIF(C23:N23,"In") -> 4 | P23: Eat as-is only
A24: P023 | B24: African pear | G24: In | H24: Peak | I24: Peak | J24: Peak | K24: In | O24: =COUNTIF(C24:N24,"Peak")+COUNTIF(C24:N24,"In") -> 5 | P24: Eat as-is only
A25: P024 | B25: Tiger nut | C25: In | D25: In | E25: In | F25: In | G25: In | I25: In | J25: In | K25: In | M25: In | N25: In | O25: =COUNTIF(C25:N25,"Peak")+COUNTIF(C25:N25,"In") -> 10 | P25: Eat as-is + recipes
A26: P025 | B26: Sugarcane | C26: In | D26: In | E26: In | J26: In | K26: In | L26: In | M26: In | N26: In | O26: =COUNTIF(C26:N26,"Peak")+COUNTIF(C26:N26,"In") -> 8 | P26: Eat as-is only
A27: P026 | B27: Custard apple (sweetsop) | D27: In | J27: In | K27: In | O27: =COUNTIF(C27:N27,"Peak")+COUNTIF(C27:N27,"In") -> 3 | P27: Eat as-is only
A28: P027 | B28: Jackfruit | G28: Peak | H28: In | O28: =COUNTIF(C28:N28,"Peak")+COUNTIF(C28:N28,"In") -> 2 | P28: Eat as-is + recipes
A29: P028 | B29: June plum | C29: In | N29: In | O29: =COUNTIF(C29:N29,"Peak")+COUNTIF(C29:N29,"In") -> 2 | P29: Eat as-is only
A30: P029 | B30: Sweet melon (golden / cantaloupe) | C30: Peak | D30: In | E30: In | F30: In | G30: Peak | H30: Peak | I30: In | J30: In | K30: In | L30: In | M30: In | N30: In | O30: =COUNTIF(C30:N30,"Peak")+COUNTIF(C30:N30,"In") -> 12 | P30: Eat as-is + recipes
A31: P030 | B31: Dates | C31: In | D31: In | E31: In | F31: Peak | G31: Peak | H31: Peak | I31: Peak | J31: In | K31: In | L31: In | M31: In | N31: In | O31: =COUNTIF(C31:N31,"Peak")+COUNTIF(C31:N31,"In") -> 12 | P31: Eat as-is + recipes
A32: P031 | B32: Apple (red & green) | C32: In | D32: In | E32: In | F32: In | G32: In | H32: In | I32: In | J32: In | K32: In | L32: In | M32: In | N32: In | O32: =COUNTIF(C32:N32,"Peak")+COUNTIF(C32:N32,"In") -> 12 | P32: Eat as-is + recipes
A33: P032 | B33: Pear | C33: In | D33: In | E33: In | F33: In | G33: In | H33: In | I33: In | J33: In | K33: In | L33: In | M33: In | N33: In | O33: =COUNTIF(C33:N33,"Peak")+COUNTIF(C33:N33,"In") -> 12 | P33: Eat as-is + recipes
A34: P033 | B34: Grapes (red / black seedless) | C34: In | D34: In | E34: In | F34: In | G34: In | H34: In | I34: In | J34: In | K34: In | L34: In | M34: In | N34: In | O34: =COUNTIF(C34:N34,"Peak")+COUNTIF(C34:N34,"In") -> 12 | P34: Eat as-is + recipes
A35: P034 | B35: Strawberry | C35: Peak | D35: Peak | E35: In | F35: In | M35: In | N35: Peak | O35: =COUNTIF(C35:N35,"Peak")+COUNTIF(C35:N35,"In") -> 6 | P35: Eat as-is + recipes
A36: P035 | B36: Blueberry | C36: In | D36: In | E36: In | F36: In | G36: In | H36: In | I36: In | J36: In | K36: In | L36: In | M36: In | N36: In | O36: =COUNTIF(C36:N36,"Peak")+COUNTIF(C36:N36,"In") -> 12 | P36: Eat as-is + recipes
A37: P036 | B37: Kiwi | C37: In | D37: In | E37: In | F37: In | G37: In | H37: In | I37: In | J37: In | K37: In | L37: In | M37: In | N37: In | O37: =COUNTIF(C37:N37,"Peak")+COUNTIF(C37:N37,"In") -> 12 | P37: Eat as-is + recipes
A38: P037 | B38: Pomegranate | C38: In | D38: In | E38: In | F38: In | G38: In | H38: In | I38: In | J38: In | K38: In | L38: In | M38: In | N38: In | O38: =COUNTIF(C38:N38,"Peak")+COUNTIF(C38:N38,"In") -> 12 | P38: Eat as-is + recipes
A39: P038 | B39: Dragon fruit | C39: In | D39: In | E39: In | F39: In | G39: In | H39: In | I39: In | J39: In | K39: In | L39: In | M39: In | N39: In | O39: =COUNTIF(C39:N39,"Peak")+COUNTIF(C39:N39,"In") -> 12 | P39: Eat as-is + recipes
A40: P039 | B40: Star fruit (carambola) | C40: In | D40: In | E40: In | F40: In | G40: In | H40: In | I40: In | J40: In | K40: In | L40: In | M40: In | N40: In | O40: =COUNTIF(C40:N40,"Peak")+COUNTIF(C40:N40,"In") -> 12 | P40: Eat as-is + recipes
...

Sheet Nutrition
A1: ID | B1: Produce | C1: kcal | D1: Fibre (g) | E1: Vitamin C (mg) | F1: Vitamin A (mcg RAE) | G1: Vitamin K (mcg) | H1: Folate (mcg) | I1: Potassium (mg) | J1: Vitamin E (mg) | K1: Vitamin B6 (mg) | L1: Magnesium (mg) | M1: Iron (mg) | N1: 1 piece (g) | O1: Piece = | P1: 1 cup (g) | Q1: Cup = | R1: Source | S1: Confidence
A2: P001 | B2: Banana | C2: 89 | D2: 2.6 | E2: 8.7 | F2: 3 | G2: 0.5 | H2: 20 | I2: 358 | J2: 0.1 | K2: 0.367 | L2: 27 | M2: 0.26 | N2: 118 | O2: 1 medium, peeled | P2: 150 | Q2: 1 cup sliced | R2: USDA FDC 173944 (SR 09040) | S2: High
A3: P002 | B3: Plantain (ripe & unripe) | C3: 122 | D3: 2.3 | E3: 18.4 | F3: 56 | G3: 0.7 | H3: 22 | I3: 499 | J3: 0.14 | K3: 0.299 | L3: 37 | M3: 0.6 | N3: 179 | O3: 1 medium, peeled | P3: 148 | Q3: 1 cup sliced | R3: USDA SR Legacy 09277 Plantains, raw | S3: High
A4: P003 | B4: Pineapple | C4: 50 | D4: 1.4 | E4: 47.8 | F4: 3 | G4: 0.7 | H4: 18 | I4: 109 | J4: 0.02 | K4: 0.112 | L4: 12 | M4: 0.29 | N4: 905 | O4: 1 medium pineapple, flesh only | P4: 165 | Q4: 1 cup chunks | R4: USDA FDC 169124 (SR 09266) | S4: High
A5: P004 | B5: Watermelon | C5: 30 | D5: 0.4 | E5: 8.1 | F5: 28 | G5: 0.1 | H5: 3 | I5: 112 | J5: 0.05 | K5: 0.045 | L5: 10 | M5: 0.24 | N5: 286 | O5: 1 wedge (1/16 of melon), flesh | P5: 152 | Q5: 1 cup diced | R5: USDA FDC 167765 (SR 09326) | S5: High
A6: P005 | B6: Pawpaw (papaya) | C6: 43 | D6: 1.7 | E6: 60.9 | F6: 47 | G6: 2.6 | H6: 37 | I6: 182 | J6: 0.3 | K6: 0.038 | L6: 21 | M6: 0.25 | N6: 275 | O6: 1 medium pawpaw, flesh only | P6: 145 | Q6: 1 cup cubed | R6: USDA FDC 169926 (SR 09226) | S6: High
A7: P006 | B7: Mango | C7: 60 | D7: 1.6 | E7: 36.4 | F7: 54 | G7: 4.2 | H7: 43 | I7: 168 | J7: 0.9 | K7: 0.119 | L7: 10 | M7: 0.16 | N7: 336 | O7: 1 medium mango, flesh only | P7: 165 | Q7: 1 cup pieces | R7: USDA FDC 169910 (SR 09176) | S7: High
A8: P007 | B8: Orange | C8: 47 | D8: 2.4 | E8: 53.2 | F8: 11 | G8: 0 | H8: 30 | I8: 181 | J8: 0.18 | K8: 0.06 | L8: 10 | M8: 0.1 | N8: 131 | O8: 1 medium, peeled | P8: 180 | Q8: 1 cup sections | R8: USDA FDC 169097 (SR 09200) | S8: High
A9: P008 | B9: Tangerine | C9: 53 | D9: 1.8 | E9: 26.7 | F9: 34 | G9: 0 | H9: 16 | I9: 166 | J9: 0.2 | K9: 0.078 | L9: 12 | M9: 0.15 | N9: 88 | O9: 1 medium, peeled | P9: 195 | Q9: 1 cup sections | R9: USDA FDC 169105 (SR 09218) | S9: High
A10: P009 | B10: Lemon | C10: 29 | D10: 2.8 | E10: 53 | F10: 1 | G10: 0 | H10: 11 | I10: 138 | J10: 0.15 | K10: 0.08 | L10: 8 | M10: 0.6 | N10: 58 | O10: 1 medium lemon, flesh without peel (juice of 1 lemon ~47 g) | P10: 212 | Q10: 1 cup sections | R10: USDA FDC 167746 (SR 09150) | S10: High
A11: P010 | B11: Lime | C11: 30 | D11: 2.8 | E11: 29.1 | F11: 2 | G11: 0.6 | H11: 8 | I11: 102 | J11: 0.22 | K11: 0.043 | L11: 6 | M11: 0.6 | N11: 67 | O11: 1 lime, flesh without peel (juice of 1 lime ~44 g) | R11: USDA FDC 168155 (SR 09159) | S11: High
A12: P011 | B12: Grapefruit | C12: 42 | D12: 1.6 | E12: 31.2 | F12: 58 | G12: 0 | H12: 13 | I12: 135 | J12: 0.13 | K12: 0.053 | L12: 9 | M12: 0.08 | N12: 246 | O12: 1 whole grapefruit, flesh (half = 123 g) | P12: 230 | Q12: 1 cup sections | R12: USDA FDC 174675 (SR 09112, pink/red) | S12: High
A13: P012 | B13: Avocado | C13: 160 | D13: 6.7 | E13: 10 | F13: 7 | G13: 21 | H13: 81 | I13: 485 | J13: 2.07 | K13: 0.257 | L13: 29 | M13: 0.55 | N13: 201 | O13: 1 medium avocado, flesh only | P13: 150 | Q13: 1 cup cubed | R13: USDA FDC 171705 (SR 09037) | S13: High
A14: P013 | B14: Guava | C14: 68 | D14: 5.4 | E14: 228.3 | F14: 31 | G14: 2.6 | H14: 49 | I14: 417 | J14: 0.73 | K14: 0.11 | L14: 22 | M14: 0.26 | N14: 55 | O14: 1 fruit | P14: 165 | Q14: 1 cup chopped | R14: USDA FDC 173044 (SR 09139) | S14: High
A15: P014 | B15: Soursop | C15: 66 | D15: 3.3 | E15: 20.6 | F15: 0 | G15: 0.4 | H15: 14 | I15: 278 | J15: 0.08 | K15: 0.059 | L15: 21 | M15: 0.6 | N15: 625 | O15: 1 fruit, pulp only | P15: 225 | Q15: 1 cup pulp | R15: USDA FDC 167763 (SR 09315) | S15: High
A16: P015 | B16: Passion fruit | C16: 97 | D16: 10.4 | E16: 30 | F16: 64 | G16: 0.7 | H16: 14 | I16: 348 | J16: 0.02 | K16: 0.1 | L16: 29 | M16: 1.6 | N16: 18 | O16: 1 fruit, pulp & seeds | P16: 236 | Q16: 1 cup pulp | R16: USDA FDC 169108 (SR 09231, purple) | S16: High
A17: P016 | B17: Coconut | C17: 354 | D17: 9 | E17: 3.3 | F17: 0 | G17: 0.2 | H17: 26 | I17: 356 | J17: 0.24 | K17: 0.054 | L17: 32 | M17: 2.43 | N17: 397 | O17: 1 medium coconut, meat only | P17: 80 | Q17: 1 cup shredded | R17: USDA FDC 170169 (SR 12104) | S17: High
A18: P017 | B18: Agbalumo (African star apple) | C18: 91 | D18: 3 | E18: 87 | I18: 654 | M18: 2.2 | N18: 30 | O18: 1 fruit, pulp only (skin & seeds removed; whole fruit ~50 g) | P18: 150 | Q18: 1 cup pulp | R18: Nigerian studies: Adeniji 2012 (3 varieties, fresh pulp: K 666-701 mg, Fe 2.2-2.3 mg, vit C 87-100 mg, moisture 73-76%); Isa 2021 (K 654 mg, Fe 2.16 mg); kcal derived from proximate | S18: Low (vitamin C reported anywhere from 4 to 100+ mg across studies; lower bound of Adeniji used)
A19: P018 | B19: Cashew apple | C19: 43 | D19: 1.7 | E19: 219 | F19: 8 | I19: 124 | L19: 10 | M19: 0.2 | N19: 70 | O19: 1 cashew apple (pseudofruit), flesh | P19: 150 | Q19: 1 cup chopped | R19: TACO Brazilian Food Composition Table 4th ed. (caju, cru); vitamin C range 200-241 mg/100 g confirmed by reviews (yellow 241, red 222 mg) | S19: Medium (vit C, kcal, K, Mg, Fe from TACO; vit A estimated from carotenoid literature)
A20: P019 | B20: Velvet tamarind | C20: 290 | D20: 3 | E20: 15 | F20: 109 | I20: 300 | M20: 4.1 | N20: 2 | O20: 1 fruit, pulp only (whole fruit with shell & seed ~4 g) | R20: Nigerian/Benin studies of Dialium guineense pulp: Nigeria dry pulp 289 kcal, K 260 mg, Fe 4.1 mg; Benin fresh pulp K 366 mg, vit C 4.5 mg; Calabar 2024 vit C 26.4 mg, vit A 109 mcg RAE | S20: Low (pulp is naturally semi-dry ~10% moisture; vit C mid-point of 4.5-26 mg; no reliable Mg/folate/E/K/B6)
A21: P020 | B21: Hog plum | C21: 46 | D21: 1.2 | E21: 28 | F21: 280 | I21: 250 | L21: 20 | M21: 0.4 | N21: 12 | O21: 1 fruit, flesh only (whole fruit ~18 g, large stone) | P21: 150 | Q21: 1 cup pulp | R21: Tiburski et al. 2011 Food Res Int (yellow mombin pulp: notable K; 100 g supplies >37% RDA vit A); Brazilian/Nigerian pulp studies (vit C 25-47 mg); TACO caja for kcal/Fe | S21: Low (vit A back-calculated from % RDA; K, Mg, fibre approximate)
A22: P021 | B22: Pepper fruit | C22: 110 | D22: 4 | I22: 290 | N22: 2 | O22: 1 fruit | R22: Nigerian studies: Ihemeje 2013 (ripe: moisture 18.7%, fibre 14.3% DW); Babcock elemental screening (K 291.5 mg/100 g); Cirad Fruits journal (protein 15%, carb 62% DW) | S22: Low (eaten as a snack in small quantities; most data dry-basis; vit C figures in literature are inconsistent so left null)
A23: P022 | B23: Monkey kola | C23: 150 | D23: 2.5 | E23: 10 | I23: 200 | M23: 1.8 | N23: 50 | O23: 1 fruit, edible pulp segments | P23: 130 | Q23: 1 cup pulp pieces | R23: Ene-Obong et al. 2016 Food Chem 193:154 (C. lepidota dried pulp K 204-209 mg/100 g); Oranusi et al. 2020 Czech J Food Sci (vit C 4.5-14.4 mg, Fe 1.79 mg); Wofu & Tariah (yellow monkey kola pulp proximate) | S23: Low (fresh-basis energy derived from proximate; vitamins mostly unreported)
A24: P023 | B24: African pear | C24: 263 | D24: 4 | E24: 12 | I24: 550 | M24: 2 | N24: 35 | O24: 1 fruit, pulp only (seed removed; whole ~55 g) | P24: 150 | Q24: 1 cup pulp | R24: Nigerian pulp studies (Ajayi & Adesanwo 2009: 138 kcal low-fat sample; Omogbai 2012: K 550.7 mg, vit C 8 mg); Cameroon safou pulp (fat 25-35 g/100 g fresh gives ~260 kcal); vit C 8-13.5 mg range | S24: Low (oily fruit: energy depends on cultivar fat content 15-35 g/100 g; Mg reported value implausible so null)
A25: P024 | B25: Tiger nut | C25: 420 | D25: 12 | E25: 6 | F25: 0 | I25: 710 | J25: 5.2 | L25: 95 | M25: 3.6 | N25: 1 | O25: 1 tuber (a handful is ~30 g) | P25: 150 | Q25: 1 cup whole dried tubers | R25: Sanchez-Zapata et al. 2012 review / PMC4619938 (Burkina Faso tubers: K 557-846 mg, Mg 100-107 mg, Fe 3.6-11.4 mg, vit C 5-27 mg, fat 25-29 g); EU retail nutrition labels (fibre 11-15 g, vit E 5.2 mg, K 783-845 mg) | S25: Medium (dried tuber basis as sold; vit E from label data; soaked 'fresh' tiger nuts will be ~30% lower per 100 g)
A26: P025 | B26: Sugarcane | C26: 60 | D26: 0.6 | E26: 3 | F26: 0 | G26: 0 | I26: 150 | J26: 0 | L26: 13 | M26: 0.6 | N26: 150 | O26: 1 x 30 cm stick, juice/pith chewed (stick weighs ~300 g) | P26: 240 | Q26: 1 cup pressed juice | R26: Indian Food Composition Tables 2017 & FNRI Philippines (sugarcane juice); applied to chewed pith | S26: Low (proxy: sugarcane juice; whole cane is not in USDA)
A27: P026 | B27: Custard apple (sweetsop) | C27: 94 | D27: 4.4 | E27: 36.3 | F27: 0 | H27: 14 | I27: 247 | K27: 0.2 | L27: 21 | M27: 0.6 | N27: 155 | O27: 1 fruit, pulp only | P27: 250 | Q27: 1 cup pulp | R27: USDA SR Legacy 09320 Sugar-apples (sweetsop), raw | S27: High
A28: P027 | B28: Jackfruit | C28: 95 | D28: 1.5 | E28: 13.7 | F28: 5 | H28: 24 | I28: 448 | J28: 0.34 | K28: 0.329 | L28: 29 | M28: 0.23 | N28: 25 | O28: 1 bulb (aril) | P28: 165 | Q28: 1 cup sliced | R28: USDA FDC 174687 (SR 09144) | S28: High
A29: P028 | B29: June plum | C29: 48 | D29: 1.5 | E29: 36 | F29: 12 | I29: 250 | L29: 15 | M29: 0.3 | N29: 70 | O29: 1 fruit, flesh only (whole fruit ~100 g, fibrous stone) | P29: 150 | Q29: 1 cup chopped | R29: Morton 1987 Fruits of Warm Climates (ambarella: vit C 42 mg, carotene ~205 IU, Fe 0.3 mg); FNRI Philippines (Spondias); K/Mg from Spondias genus | S29: Low (K and Mg are genus proxies)
A30: P029 | B30: Sweet melon (golden / cantaloupe) | C30: 34 | D30: 0.9 | E30: 36.7 | F30: 169 | G30: 2.5 | H30: 21 | I30: 267 | J30: 0.05 | K30: 0.072 | L30: 12 | M30: 0.21 | N30: 552 | O30: 1 medium melon, flesh only (1 wedge = 69 g) | P30: 160 | Q30: 1 cup cubed | R30: USDA FDC 169092 (SR 09181) | S30: High
A31: P030 | B31: Dates | C31: 282 | D31: 8 | E31: 0.4 | F31: 0 | G31: 2.7 | H31: 19 | I31: 656 | J31: 0.05 | K31: 0.165 | L31: 43 | M31: 1.02 | N31: 7 | O31: 1 date, pitted (medjool = 24 g) | P31: 147 | Q31: 1 cup chopped | R31: USDA FDC 171726 (SR 09421, deglet noor) | S31: High
A32: P031 | B32: Apple (red & green) | C32: 52 | D32: 2.4 | E32: 4.6 | F32: 3 | G32: 2.2 | H32: 3 | I32: 107 | J32: 0.18 | K32: 0.041 | L32: 5 | M32: 0.12 | N32: 182 | O32: 1 medium, with skin | P32: 125 | Q32: 1 cup chopped | R32: USDA FDC 171688 (SR 09003) | S32: High
A33: P032 | B33: Pear | C33: 57 | D33: 3.1 | E33: 4.3 | F33: 1 | G33: 4.4 | H33: 7 | I33: 116 | J33: 0.12 | K33: 0.029 | L33: 7 | M33: 0.18 | N33: 178 | O33: 1 medium | P33: 140 | Q33: 1 cup sliced | R33: USDA FDC 169118 (SR 09252) | S33: High
A34: P033 | B34: Grapes (red / black seedless) | C34: 69 | D34: 0.9 | E34: 3.2 | F34: 3 | G34: 14.6 | H34: 2 | I34: 191 | J34: 0.19 | K34: 0.086 | L34: 7 | M34: 0.36 | N34: 5 | O34: 1 grape | P34: 151 | Q34: 1 cup | R34: USDA FDC 174683 (SR 09132, red/green) | S34: High
A35: P034 | B35: Strawberry | C35: 32 | D35: 2 | E35: 58.8 | F35: 1 | G35: 2.2 | H35: 24 | I35: 153 | J35: 0.29 | K35: 0.047 | L35: 13 | M35: 0.41 | N35: 12 | O35: 1 medium berry | P35: 152 | Q35: 1 cup halves | R35: USDA FDC 167762 (SR 09316) | S35: High
A36: P035 | B36: Blueberry | C36: 57 | D36: 2.4 | E36: 9.7 | F36: 3 | G36: 19.3 | H36: 6 | I36: 77 | J36: 0.57 | K36: 0.052 | L36: 6 | M36: 0.28 | N36: 148 | O36: 1 cup (approx 100 berries) | P36: 148 | Q36: 1 cup | R36: USDA FDC 171711 (SR 09050) | S36: High
A37: P036 | B37: Kiwi | C37: 61 | D37: 3 | E37: 92.7 | F37: 4 | G37: 40.3 | H37: 25 | I37: 312 | J37: 1.46 | K37: 0.063 | L37: 17 | M37: 0.31 | N37: 69 | O37: 1 fruit, peeled | P37: 180 | Q37: 1 cup sliced | R37: USDA FDC 168153 (SR 09148, green) | S37: High
A38: P037 | B38: Pomegranate | C38: 83 | D38: 4 | E38: 10.2 | F38: 0 | G38: 16.4 | H38: 38 | I38: 236 | J38: 0.6 | K38: 0.075 | L38: 12 | M38: 0.3 | N38: 282 | O38: 1 fruit, arils only | P38: 174 | Q38: 1 cup arils | R38: USDA FDC 169134 (SR 09286) | S38: High
A39: P038 | B39: Dragon fruit | C39: 52 | D39: 2 | E39: 9 | F39: 0 | I39: 260 | L39: 36 | M39: 0.7 | N39: 280 | O39: 1 medium fruit, flesh only | P39: 150 | Q39: 1 cup cubed | R39: Le Bellec et al. 2006 Fruits 61:237 review; Malaysian & Taiwan food composition data (white-flesh Hylocereus undatus) | S39: Low (no USDA SR/Foundation entry; values vary by flesh colour)
A40: P039 | B40: Star fruit (carambola) | C40: 31 | D40: 2.8 | E40: 34.4 | F40: 3 | G40: 0 | H40: 12 | I40: 133 | J40: 0.15 | K40: 0.017 | L40: 10 | M40: 0.08 | N40: 91 | O40: 1 medium fruit | P40: 132 | Q40: 1 cup cubed | R40: USDA FDC 171715 (SR 09060) | S40: High
...

Sheet Recipes
A1: ID | B1: Recipe | C1: Category | D1: Subtype | E1: Meal | F1: Inspired by | G1: Source | H1: Source URL | I1: Reference image URL | J1: Local adaptation | K1: Serve with / you add | L1: Goal tags | M1: Diet | N1: Prep (min) | O1: Cook (min) | P1: Total (min) | Q1: Effort tier | R1: Servings | S1: Est. kcal / serving | T1: Est. protein (g) / serving | U1: Produce (g) / serving | V1: Fibre (g) | W1: Vitamin C (mg) | X1: Vitamin A (mcg RAE) | Y1: Vitamin K (mcg) | Z1: Folate (mcg) | AA1: Potassium (mg) | AB1: Vitamin E (mg) | AC1: Vitamin B6 (mg) | AD1: Magnesium (mg) | AE1: Iron (mg) | AF1: Fibre % daily | AG1: Vitamin C % daily | AH1: Vitamin A % daily | AI1: Vitamin K % daily | AJ1: Folate % daily | AK1: Potassium % daily | AL1: Vitamin E % daily | AM1: Vitamin B6 % daily | AN1: Magnesium % daily | AO1: Iron % daily | AP1: Strongest nutrient | AQ1: Health tagline | AR1: Also strong in | AS1: Health note | AT1: Hero produce | AU1: Basket items | AV1: Other items | AW1: Basket coverage | AX1: Hits target? | AY1: Seasonal ingredients | AZ1: Method | BA1: Tip | BB1: Status
A2: R015 | B2: Mango & Passion Fruit Overnight Oats | C2: Breakfast Plates | D2: Fruit & oats | E2: Breakfast | F2: Bircher muesli (Switzerland) / overnight oats | G2: BBC Good Food | H2: https://www.bbcgoodfood.com/recipes/overnight-oats | I2: https://images.immediate.co.uk/production/volatile/sites/30/2020/08/overnight-oats-32a2747.jpg?resize=440%2C230 | J2: Mango and passion fruit on top, tiger nut milk as an option. | K2: You add: rolled oats, yoghurt or milk, honey. | L2: Training, Weight management | M2: Vegetarian | N2: 10 | O2: 0 | P2: =N2+O2 -> 10 | Q2: =IF(O2=0,"No-cook",IF(P2<=25,"Quick","Standard")) -> No-cook | R2: 2 | S2: 380 | T2: 14 | U2: =SUMIFS('Recipe Ingredients'!$I$2:$I$2500,'Recipe Ingredients'!$A$2:$A$2500,A2)/R2 -> 186 | V2: =SUMIFS('Recipe Ingredients'!$J$2:$J$2500,'Recipe Ingredients'!$A$2:$A$2500,A2)/R2 -> 4.56 | W2: =SUMIFS('Recipe Ingredients'!$K$2:$K$2500,'Recipe Ingredients'!$A$2:$A$2500,A2)/R2 -> 66.552 | X2: =SUMIFS('Recipe Ingredients'!$L$2:$L$2500,'Recipe Ingredients'!$A$2:$A$2500,A2)/R2 -> 102.24 | Y2: =SUMIFS('Recipe Ingredients'!$M$2:$M$2500,'Recipe Ingredients'!$A$2:$A$2500,A2)/R2 -> 7.182 | Z2: =SUMIFS('Recipe Ingredients'!$N$2:$N$2500,'Recipe Ingredients'!$A$2:$A$2500,A2)/R2 -> 74.76 | AA2: =SUMIFS('Recipe Ingredients'!$O$2:$O$2500,'Recipe Ingredients'!$A$2:$A$2500,A2)/R2 -> 344.88 | AB2: =SUMIFS('Recipe Ingredients'!$P$2:$P$2500,'Recipe Ingredients'!$A$2:$A$2500,A2)/R2 -> 1.5156 | AC2: =SUMIFS('Recipe Ingredients'!$Q$2:$Q$2500,'Recipe Ingredients'!$A$2:$A$2500,A2)/R2 -> 0.21792 | AD2: =SUMIFS('Recipe Ingredients'!$R$2:$R$2500,'Recipe Ingredients'!$A$2:$A$2500,A2)/R2 -> 22.02 | AE2: =SUMIFS('Recipe Ingredients'!$S$2:$S$2500,'Recipe Ingredients'!$A$2:$A$2500,A2)/R2 -> 0.5568 | AF2: =IFERROR(V2/'Start Here'!$C$10,0) -> 0.1824 | AG2: =IFERROR(W2/'Start Here'!$C$11,0) -> 0.8319 | AH2: =IFERROR(X2/'Start Here'!$C$12,0) -> 0.1278 | AI2: =IFERROR(Y2/'Start Here'!$C$13,0) -> 0.09576 | AJ2: =IFERROR(Z2/'Start Here'!$C$14,0) -> 0.3738 | AK2: =IFERROR(AA2/'Start Here'!$C$15,0) -> 0.17244 | AL2: =IFERROR(AB2/'Start Here'!$C$16,0) -> 0.1263 | AM2: =IFERROR(AC2/'Start Here'!$C$17,0) -> 0.15565714 | AN2: =IFERROR(AD2/'Start Here'!$C$18,0) -> 0.05872 | AO2: =IFERROR(AE2/'Start Here'!$C$19,0) -> 0.039771429 | AP2: =IFERROR(SUBSTITUTE(INDEX($AF$1:$AO$1,MATCH(MAX(AF2:AO2),AF2:AO2,0))," % daily",""),"") -> Vitamin C | AQ2: =IF(MAX(AF2:AO2)>=0.15,"Best for better "&IF(LEFT(AP2,7)="Vitamin","vitamin "&MID(AP2,9,3),LOWER(AP2))&" intake: one serving gives about "&TEXT(MAX(AF2:AO2),"0%")&" of your daily "&IF(LEFT(AP2,7)="Vitamin","vitamin "&MID(AP2,9,3),LOWER(AP2))&" from the produce alone.","A lighter plate: top nutrient is "&IF(LEFT(AP2,7)="Vitamin","vitamin "&MID(AP2,9,3),LOWER(AP2))&" at about "&TEXT(MAX(AF2:AO2),"0%")&" of a day.") -> Best for better vitamin C intake: one serving gives about 83% of your daily vitamin C from the produce alone. | AR2: =IF(LEN(IF(AND(AF2>=0.25,"Fibre"<>AP2),"Fibre ("&TEXT(AF2,"0%")&")|","")&IF(AND(AG2>=0.25,"Vitamin C"<>AP2),"Vitamin C ("&TEXT(AG2,"0%")&")|","")&IF(AND(AH2>=0.25,"Vitamin A"<>AP2),"Vitamin A ("&TEXT(AH2,"0%")&")|","")&IF(AND(AI2>=0.25,"Vitamin K"<>AP2),"Vitamin K ("&TEXT(AI2,"0%")&")|","")&IF(AND(AJ2>=0.25,"Folate"<>AP2),"Folate ("&TEXT(AJ2,"0%")&")|","")&IF(AND(AK2>=0.25,"Potassium"<>AP2),"Potassium ("&TEXT(AK2,"0%")&")|","")&IF(AND(AL2>=0.25,"Vitamin E"<>AP2),"Vitamin E ("&TEXT(AL2,"0%")&")|","")&IF(AND(AM2>=0.25,"Vitamin B6"<>AP2),"Vitamin B6 ("&TEXT(AM2,"0%")&")|","")&IF(AND(AN2>=0.25,"Magnesium"<>AP2),"Magnesium ("&TEXT(AN2,"0%")&")|","")&IF(AND(AO2>=0.25,"Iron"<>AP2),"Iron ("&TEXT(AO2,"0%")&")|",""))=0,"",SUBSTITUTE(LEFT(IF(AND(AF2>=0.25,"Fibre"<>AP2),"Fibre ("&TEXT(AF2,"0%")&")|","")&IF(AND(AG2>=0.25,"Vitamin C"<>AP2),"Vitamin C ("&TEXT(AG2,"0%")&")|","")&IF(AND(AH2>=0.25,"Vitamin A"<>AP2),"Vitamin A ("&TEXT(AH2,"0%")&")|","")&IF(AND(AI2>=0.25,"Vitamin K"<>AP2),"Vitamin K ("&TEXT(AI2,"0%")&")|","")&IF(AND(AJ2>=0.25,"Folate"<>AP2),"Folate ("&TEXT(AJ2,"0%")&")|","")&IF(AND(AK2>=0.25,"Potassium"<>AP2),"Potassium ("&TEXT(AK2,"0%")&")|","")&IF(AND(AL2>=0.25,"Vitamin E"<>AP2),"Vitamin E ("&TEXT(AL2,"0%")&")|","")&IF(AND(AM2>=0.25,"Vitamin B6"<>AP2),"Vitamin B6 ("&TEXT(AM2,"0%")&")|","")&IF(AND(AN2>=0.25,"Magnesium"<>AP2),"Magnesium ("&TEXT(AN2,"0%")&")|","")&IF(AND(AO2>=0.25,"Iron"<>AP2),"Iron ("&TEXT(AO2,"0%")&")|",""),LEN(IF(AND(AF2>=0.25,"Fibre"<>AP2),"Fibre ("&TEXT(AF2,"0%")&")|","")&IF(AND(AG2>=0.25,"Vitamin C"<>AP2),"Vitamin C ("&TEXT(AG2,"0%")&")|","")&IF(AND(AH2>=0.25,"Vitamin A"<>AP2),"Vitamin A ("&TEXT(AH2,"0%")&")|","")&IF(AND(AI2>=0.25,"Vitamin K"<>AP2),"Vitamin K ("&TEXT(AI2,"0%")&")|","")&IF(AND(AJ2>=0.25,"Folate"<>AP2),"Folate ("&TEXT(AJ2,"0%")&")|","")&IF(AND(AK2>=0.25,"Potassium"<>AP2),"Potassium ("&TEXT(AK2,"0%")&")|","")&IF(AND(AL2>=0.25,"Vitamin E"<>AP2),"Vitamin E ("&TEXT(AL2,"0%")&")|","")&IF(AND(AM2>=0.25,"Vitamin B6"<>AP2),"Vitamin B6 ("&TEXT(AM2,"0%")&")|","")&IF(AND(AN2>=0.25,"Magnesium"<>AP2),"Magnesium ("&TEXT(AN2,"0%")&")|","")&IF(AND(AO2>=0.25,"Iron"<>AP2),"Iron ("&TEXT(AO2,"0%")&")|",""))-1),"|",", ")) -> Folate (37%) | AS2: Mango brings vitamin A (as beta-carotene), vitamin C and folate. Passion fruit is high in fibre and vitamin A and C. | AT2: Mango, Passion fruit | AU2: =COUNTIFS('Recipe Ingredients'!$A$2:$A$2500,A2,'Recipe Ingredients'!$G$2:$G$2500,"Basket") -> 2 | AV2: =COUNTIFS('Recipe Ingredients'!$A$2:$A$2500,A2,'Recipe Ingredients'!$G$2:$G$2500,"Protein")+COUNTIFS('Recipe Ingredients'!$A$2:$A$2500,A2,'Recipe Ingredients'!$G$2:$G$2500,"Pantry") -> 5 | AW2: =IFERROR(AU2/(AU2+AV2),0) -> 0.28571429 | AX2: =IF(AW2>='Start Here'!$C$6,"Yes","No") -> No | AY2: Mango (Feb-May, Aug-Sep); Passion fruit (Jan-Mar, May-Jun, Aug-Nov) | AZ2: 1. Stir oats, milk, yoghurt and chia together in two jars. 2. Cover and refrigerate overnight. 3. In the morning, top with diced mango and passion fruit pulp. 4. Drizzle with honey if you like. | BA2: Make 3 days at once for a week of grab-and-go breakfasts. | BB2: Draft
