Workbook

Sheet Start Here
B2: Basket: Produce & Recipe Library
B3: Nigerian-market produce catalogue, seasonal calendar and 75 global recipes adapted to local ingredients. Research compiled 11 Oct 2026.
B5: Settings
B6: Basket coverage target | C6: 0.8 | D6: Share of a recipe's non-staple ingredients that should come from Basket. Set at 80% from the positioning brief. Change it and every recipe re-scores.
B8: At a glance
B9: Produce items catalogued | C9: =COUNTA(Produce!A2:A500)
B10: Recipes | C10: =COUNTA(Recipes!A2:A500)
B11: Recipes hitting the coverage target | C11: =COUNTIF(Recipes!T2:T500,"Yes")
B12: Average Basket coverage | C12: =AVERAGE(Recipes!S2:S500)
B13: Produce in season this month | C13: =COUNTIF(Produce!J2:J500,"Peak")+COUNTIF(Produce!J2:J500,"In")
B14: Produce at peak this month | C14: =COUNTIF(Produce!J2:J500,"Peak")
B15: Eat-as-is-only fruits (seasonal drops) | C15: =COUNTIF(Produce!F2:F500,"Eat as-is only")
B16: Vegan / plant-based recipes | C16: =COUNTIF(Recipes!H2:H500,"Vegan")
B17: No-cook recipes | C17: =COUNTIF(Recipes!L2:L500,"No-cook")
B19: What's in each tab
B20: Produce | C20: Every fruit, vegetable, herb and nut worth stocking: local names, origin, season, role (eat as-is / recipes), sell unit, competitor benchmark price, storage, sourcing region, launch tier, and how many recipes use it.
B21: Seasonal Calendar | C21: Month-by-month availability. Peak and In-season cells are colour coded. The Produce tab reads this to show what is in season today.
B22: Recipes | C22: 75 recipes (no drinks): the global dish each is based on, what changed for Nigeria, goal and diet tags, timings, effort tier, estimated nutrition, method, and Basket coverage scored by formula.
B23: Recipe Ingredients | C23: One row per ingredient with quantity, unit and source (Basket / Protein / Pantry / Staple). This is the table the coverage scores and recipe counts are built on. Add or edit rows here.
B24: Box Ideas | C24: Seasonal drops and themed baskets built from the catalogue, each linked to the recipes it unlocks.
B25: Market Scan | C25: What the Lagos players and the four international meal kits do, what to borrow, and the gap Basket can own.
B26: Sources | C26: Every site and document used.
B28: How to edit
B29: Yellow cells | C29: Your inputs: coverage target, Basket price, Stock it?, and recipe Status. Everything else updates from them.
B30: Add a recipe | C30: Add a row on Recipes (copy the formulas in Q to T down), then add its ingredients on Recipe Ingredients with the same Recipe ID. Put the Produce ID in column F for anything Basket sells.
B31: Add produce | C31: Add a row on Produce and a matching row on Seasonal Calendar with the same ID. Mark months 'Peak' or 'In'.
B32: Source column | C32: Basket = produce we sell. Protein and Pantry count against coverage. Staple (salt, oil, water, ice, pepper) is ignored.
B34: Key findings
B35: • Lagos online produce splits two ways: raw grocery (Mint Foods, Home Basket, SwanCape) and finished health products (The Fresh Place juices at N3,500 to N4,500, salad trays at N30,000 to N50,000). Nobody connects raw produce to light, global recipes. That is the lane this library is built for.
B36: • SwanCape already turns a dish into a priced ingredient list, but only for Egusi, Jollof, Ogbono, Pepper soup and Efo riro. The recipe library here deliberately avoids competing on traditional soups.
B37: • Local vs imported is the biggest price lever. Mint Foods lists 4 local lemons at N1,900 and 5 Dutch lemons at N13,800. Local cauliflower N2,750 a head vs imported N16,900. Recipes default to local produce; imported items are premium add-ons.
B38: • Seasonality creates natural drops: agbalumo Dec-May, mango Feb-May, citrus best Oct-Jan, fresh corn Apr-Aug, ube May-Sep, guava Feb-Mar and Aug-Sep (Kitchen Butterfly calendar).
B39: • Meal-kit playbook worth copying: goal menus (HelloFresh), effort tiers and swaps (Home Chef), seasonal editorial and diet filters (Marley Spoon), part-prepped produce (Sunbasket). Every recipe here carries goal, diet and effort tags so the app can filter the same way.
B41: Caveats
B42: • Calories and protein are rough per-serving estimates for filtering and planning. Get them checked before publishing numbers in the app.
B43: • Season confidence: 'Sourced' rows come from the Kitchen Butterfly Nigerian Seasonal Produce Calendar (V1.3). 'Verify' rows are general market knowledge. Confirm both with your suppliers in the pilot.
B44: • Benchmark prices are competitor retail prices captured on 11 Oct 2026, not wholesale cost. Only items with a published price have one. Basket price is left for you to fill.
B45: • Freshcart.ng blocked automated access and has no indexed pages, so it is not in the scan. Home Basket's catalogue loads client-side, so only its positioning was captured.

Sheet Produce
A1: ID | B1: Produce | C1: Local names | D1: Category | E1: Origin | F1: Role | G1: Availability | H1: Season | I1: Peak | J1: In season now? | K1: Season confidence | L1: Sell unit | M1: Benchmark price (N) | N1: Benchmark unit | O1: Benchmark source | P1: Basket price (N) | Q1: Stock it? | R1: Launch tier | S1: Used in # recipes | T1: Storage | U1: Shelf life | V1: Sourcing region | W1: Best for | X1: Notes
A2: P001 | B2: Banana | C2: Ogede wewe (Yor), Ayaba (Hau) | D2: Fruit | E2: Local | F2: Eat as-is + recipes | G2: Year-round | H2: All year | J2: =IFERROR(IF(INDEX('Seasonal Calendar'!$C$2:$N$500,MATCH(A2,'Seasonal Calendar'!$A$2:$A$500,0),MONTH(TODAY()))="","Out",INDEX('Seasonal Calendar'!$C$2:$N$500,MATCH(A2,'Seasonal Calendar'!$A$2:$A$500,0),MONTH(TODAY()))),"") | K2: Verify | L2: Hand (~1kg) | M2: 1850 | N2: 1kg | O2: The Fresh Place (thefreshplace.ng), 17 Oct 2026 | Q2: Y | R2: Core | S2: =COUNTIF('Recipe Ingredients'!$F$2:$F$2000,A2) | T2: Room temp; fridge once fully ripe (skin darkens, flesh holds) | U2: 3-5 days | V2: Ondo, Ogun, Cross River, Edo | W2: Training, Energy | X2: Most-used fruit in the recipe library. Sell spotty, very ripe bananas as discounted 'smoothie bananas' rather than writing them off.
A3: P002 | B3: Plantain (ripe & unripe) | C3: Ogede agbagba (Yor), Agade (Hau) | D3: Fruit (cooking) | E3: Local | F3: Recipe ingredient | G3: Year-round | H3: All year | J3: =IFERROR(IF(INDEX('Seasonal Calendar'!$C$2:$N$500,MATCH(A3,'Seasonal Calendar'!$A$2:$A$500,0),MONTH(TODAY()))="","Out",INDEX('Seasonal Calendar'!$C$2:$N$500,MATCH(A3,'Seasonal Calendar'!$A$2:$A$500,0),MONTH(TODAY()))),"") | K3: Verify | L3: Finger / bunch | Q3: Y | R3: Core | S3: =COUNTIF('Recipe Ingredients'!$F$2:$F$2000,A3) | T3: Room temp; ripens in 3-6 days | U3: 5-10 days | V3: Ondo, Edo, Ogun, Cross River | W3: Training, Energy | X3: Sell by ripeness stage (green, yellow, black-spotted) so recipes get the right one.
A4: P003 | B4: Pineapple | C4: Ope oyinbo (Yor), Abarba (Hau) | D4: Fruit | E4: Local | F4: Eat as-is + recipes | G4: Year-round | H4: All year | J4: =IFERROR(IF(INDEX('Seasonal Calendar'!$C$2:$N$500,MATCH(A4,'Seasonal Calendar'!$A$2:$A$500,0),MONTH(TODAY()))="","Out",INDEX('Seasonal Calendar'!$C$2:$N$500,MATCH(A4,'Seasonal Calendar'!$A$2:$A$500,0),MONTH(TODAY()))),"") | K4: Verify | L4: Piece | M4: 2000 | N4: 1 pc (Cotonou pineapple) | O4: The Fresh Place (thefreshplace.ng), 17 Oct 2026; Bendel pineapple N3,000/pc | Q4: Y | R4: Core | S4: =COUNTIF('Recipe Ingredients'!$F$2:$F$2000,A4) | T4: Room temp until fragrant; fridge once cut | U4: 3-5 days whole, 3 days cut | V4: Edo (Bendel), Ogun, Oyo, Delta | W4: Hydration, Wellness | X4: Bendel and sugarloaf types are sweeter than imported. Price gap between sellers is wide (N1,300 vs N3,000).
A5: P004 | B5: Watermelon | C5: Bara (Yor), Kankana (Hau) | D5: Fruit | E5: Local | F5: Eat as-is + recipes | G5: Year-round | H5: All year | I5: Dec-Apr | J5: =IFERROR(IF(INDEX('Seasonal Calendar'!$C$2:$N$500,MATCH(A5,'Seasonal Calendar'!$A$2:$A$500,0),MONTH(TODAY()))="","Out",INDEX('Seasonal Calendar'!$C$2:$N$500,MATCH(A5,'Seasonal Calendar'!$A$2:$A$500,0),MONTH(TODAY()))),"") | K5: Verify | L5: Piece (S/M/L) or half | M5: 5500 | N5: 1 pc (size not stated) | O5: The Fresh Place (thefreshplace.ng), 17 Oct 2026 | Q5: Y | R5: Core | S5: =COUNTIF('Recipe Ingredients'!$F$2:$F$2000,A5) | T5: Whole at room temp; cut in fridge, wrapped | U5: 1-2 weeks whole, 3 days cut | V5: Kano, Kaduna, Jigawa, Plateau | W5: Hydration, Weight management | X5: Listed by Kitchen Butterfly as available all year; northern supply heaviest in the dry season.
A6: P005 | B6: Pawpaw (papaya) | C6: Ibepe (Yor), Gwanda (Hau) | D6: Fruit | E6: Local | F6: Eat as-is + recipes | G6: Year-round | H6: All year | J6: =IFERROR(IF(INDEX('Seasonal Calendar'!$C$2:$N$500,MATCH(A6,'Seasonal Calendar'!$A$2:$A$500,0),MONTH(TODAY()))="","Out",INDEX('Seasonal Calendar'!$C$2:$N$500,MATCH(A6,'Seasonal Calendar'!$A$2:$A$500,0),MONTH(TODAY()))),"") | K6: Verify | L6: Piece | M6: 3000 | N6: 1 pc | O6: The Fresh Place (thefreshplace.ng), 17 Oct 2026; listed out of stock | Q6: Y | R6: Core | S6: =COUNTIF('Recipe Ingredients'!$F$2:$F$2000,A6) | T6: Ripen at room temp; fridge when soft | U6: 2-4 days ripe | V6: Nationwide | W6: Gut health, Weight management | X6: Unripe (green) pawpaw is a recipe ingredient too (green papaya salad).
A7: P006 | B7: Mango | C7: Mangoro (Yor/Hau) | D7: Fruit | E7: Local | F7: Eat as-is + recipes | G7: Seasonal | H7: Feb-May, Aug-Sep | I7: Mar-Apr | J7: =IFERROR(IF(INDEX('Seasonal Calendar'!$C$2:$N$500,MATCH(A7,'Seasonal Calendar'!$A$2:$A$500,0),MONTH(TODAY()))="","Out",INDEX('Seasonal Calendar'!$C$2:$N$500,MATCH(A7,'Seasonal Calendar'!$A$2:$A$500,0),MONTH(TODAY()))),"") | K7: Sourced | L7: Piece / 1kg | M7: 500 | N7: 1 pc (cherry mango) | O7: The Fresh Place (thefreshplace.ng), 17 Oct 2026; listed out of stock | Q7: Seasonal | R7: Seasonal drop | S7: =COUNTIF('Recipe Ingredients'!$F$2:$F$2000,A7) | T7: Room temp to ripen; fridge when ripe | U7: 3-5 days ripe | V7: Oyo (Ogbomoso), Benue, Kaduna, Niger | W7: Energy, Wellness | X7: Main season Feb-May with a smaller Aug-Sep run. Varieties worth naming on the app: Ogbomoso, Julie, cherry, 'German'.
A8: P007 | B8: Orange | C8: Osan (Yor), Oroma (Igbo), Lemu (Hau) | D8: Fruit (citrus) | E8: Local + imported | F8: Eat as-is + recipes | G8: Year-round | H8: All year | I8: Oct-Jan | J8: =IFERROR(IF(INDEX('Seasonal Calendar'!$C$2:$N$500,MATCH(A8,'Seasonal Calendar'!$A$2:$A$500,0),MONTH(TODAY()))="","Out",INDEX('Seasonal Calendar'!$C$2:$N$500,MATCH(A8,'Seasonal Calendar'!$A$2:$A$500,0),MONTH(TODAY()))),"") | K8: Sourced | L8: Piece / dozen | M8: 200 | N8: 1 pc local | O8: The Fresh Place (thefreshplace.ng), 17 Oct 2026; local dozen N2,400; imported N950/pc, N10,800/dozen | Q8: Y | R8: Core | S8: =COUNTIF('Recipe Ingredients'!$F$2:$F$2000,A8) | T8: Room temp 1 week; fridge 2-3 weeks | U8: 1-3 weeks | V8: Benue (citrus belt), Ogun, Oyo | W8: Wellness, Hydration | X8: Available all year with varying quality; best fruit Oct-Dec per Kitchen Butterfly.
A9: P008 | B9: Tangerine | D9: Fruit (citrus) | E9: Local + imported | F9: Eat as-is + recipes | G9: Year-round | H9: All year | I9: Oct-Jan | J9: =IFERROR(IF(INDEX('Seasonal Calendar'!$C$2:$N$500,MATCH(A9,'Seasonal Calendar'!$A$2:$A$500,0),MONTH(TODAY()))="","Out",INDEX('Seasonal Calendar'!$C$2:$N$500,MATCH(A9,'Seasonal Calendar'!$A$2:$A$500,0),MONTH(TODAY()))),"") | K9: Sourced | L9: Piece | M9: 300 | N9: 1 pc local | O9: The Fresh Place (thefreshplace.ng), 17 Oct 2026; listed out of stock; imported clementine N850/pc, N10,800/dozen | Q9: Y | R9: Core | S9: =COUNTIF('Recipe Ingredients'!$F$2:$F$2000,A9) | T9: Room temp 1 week; fridge 2 weeks | U9: 1-2 weeks | V9: Benue, Ogun | W9: Wellness | X9: Local vs imported price is nearly 3x.
A10: P009 | B10: Lemon | D10: Fruit (citrus) | E10: Local + imported | F10: Recipe ingredient | G10: Year-round | H10: All year | I10: Oct-Jan | J10: =IFERROR(IF(INDEX('Seasonal Calendar'!$C$2:$N$500,MATCH(A10,'Seasonal Calendar'!$A$2:$A$500,0),MONTH(TODAY()))="","Out",INDEX('Seasonal Calendar'!$C$2:$N$500,MATCH(A10,'Seasonal Calendar'!$A$2:$A$500,0),MONTH(TODAY()))),"") | K10: Verify | L10: Piece | M10: 300 | N10: 1 pc local | O10: The Fresh Place (thefreshplace.ng), 17 Oct 2026; local dozen N4,800; imported N950/pc, N10,200/dozen | Q10: Y | R10: Core | S10: =COUNTIF('Recipe Ingredients'!$F$2:$F$2000,A10) | T10: Fridge | U10: 2-3 weeks | V10: Benue, Plateau | W10: Wellness | X10: Used in more recipes than almost anything else. Strong case for local-only.
A11: P010 | B11: Lime | C11: Osan wewe (Yor) | D11: Fruit (citrus) | E11: Local | F11: Recipe ingredient | G11: Year-round | H11: All year | I11: Oct-Jan | J11: =IFERROR(IF(INDEX('Seasonal Calendar'!$C$2:$N$500,MATCH(A11,'Seasonal Calendar'!$A$2:$A$500,0),MONTH(TODAY()))="","Out",INDEX('Seasonal Calendar'!$C$2:$N$500,MATCH(A11,'Seasonal Calendar'!$A$2:$A$500,0),MONTH(TODAY()))),"") | K11: Sourced | L11: Piece / pack of 4 | Q11: Y | R11: Core | S11: =COUNTIF('Recipe Ingredients'!$F$2:$F$2000,A11) | T11: Fridge | U11: 2-3 weeks | V11: Benue, Ogun, Oyo | W11: Wellness | X11: Best fruit Oct-Dec (Kitchen Butterfly). Workhorse acid for salsas, dressings and drinks.
A12: P011 | B12: Grapefruit | D12: Fruit (citrus) | E12: Local | F12: Eat as-is + recipes | G12: Year-round | H12: All year | I12: Oct-Jan | J12: =IFERROR(IF(INDEX('Seasonal Calendar'!$C$2:$N$500,MATCH(A12,'Seasonal Calendar'!$A$2:$A$500,0),MONTH(TODAY()))="","Out",INDEX('Seasonal Calendar'!$C$2:$N$500,MATCH(A12,'Seasonal Calendar'!$A$2:$A$500,0),MONTH(TODAY()))),"") | K12: Verify | L12: Piece | Q12: N | R12: Later | S12: =COUNTIF('Recipe Ingredients'!$F$2:$F$2000,A12) | T12: Room temp / fridge | U12: 2-3 weeks | V12: Benue | W12: Weight management | X12: Niche but cheap locally. Good add-on for citrus boxes.
A13: P012 | B13: Avocado | C13: Pia (Yor) | D13: Fruit | E13: Local + imported | F13: Eat as-is + recipes | G13: Year-round | H13: All year | J13: =IFERROR(IF(INDEX('Seasonal Calendar'!$C$2:$N$500,MATCH(A13,'Seasonal Calendar'!$A$2:$A$500,0),MONTH(TODAY()))="","Out",INDEX('Seasonal Calendar'!$C$2:$N$500,MATCH(A13,'Seasonal Calendar'!$A$2:$A$500,0),MONTH(TODAY()))),"") | K13: Verify | L13: Piece | M13: 2000 | N13: 1 pc medium | O13: The Fresh Place (thefreshplace.ng), 17 Oct 2026; big N2,500, listed out of stock | Q13: Y | R13: Core | S13: =COUNTIF('Recipe Ingredients'!$F$2:$F$2000,A13) | T13: Room temp to ripen; fridge once ripe | U13: 2-3 days ripe | V13: Southwest, Cross River, Plateau | W13: Training, Wellness | X13: Local supply and quality swing through the year. Confirm local peak months with suppliers. Mint sells a ready-to-eat 'eat me' pack, worth copying.
A14: P013 | B14: Guava | C14: Gova (Yor), Gwaba (Hau) | D14: Fruit | E14: Local + imported | F14: Eat as-is + recipes | G14: Seasonal | H14: Feb-Mar, Aug-Sep | I14: Feb-Mar | J14: =IFERROR(IF(INDEX('Seasonal Calendar'!$C$2:$N$500,MATCH(A14,'Seasonal Calendar'!$A$2:$A$500,0),MONTH(TODAY()))="","Out",INDEX('Seasonal Calendar'!$C$2:$N$500,MATCH(A14,'Seasonal Calendar'!$A$2:$A$500,0),MONTH(TODAY()))),"") | K14: Sourced | L14: Piece / 1kg | M14: 16000 | N14: 1kg imported | O14: The Fresh Place (thefreshplace.ng), 17 Oct 2026; listed out of stock | Q14: Seasonal | R14: Seasonal drop | S14: =COUNTIF('Recipe Ingredients'!$F$2:$F$2000,A14) | T14: Room temp; fridge when soft | U14: 3-4 days | V14: Nationwide | W14: Wellness | X14: Two short local windows. Imported guava sells at a premium.
A15: P014 | B15: Soursop | D15: Fruit | E15: Local | F15: Eat as-is + recipes | G15: Seasonal | H15: Dec-Mar, May-Aug, Oct | I15: Feb-Mar | J15: =IFERROR(IF(INDEX('Seasonal Calendar'!$C$2:$N$500,MATCH(A15,'Seasonal Calendar'!$A$2:$A$500,0),MONTH(TODAY()))="","Out",INDEX('Seasonal Calendar'!$C$2:$N$500,MATCH(A15,'Seasonal Calendar'!$A$2:$A$500,0),MONTH(TODAY()))),"") | K15: Sourced | L15: Piece / 1kg | M15: 5500 | N15: 1kg | O15: The Fresh Place (thefreshplace.ng), 17 Oct 2026; listed out of stock | Q15: Seasonal | R15: Seasonal drop | S15: =COUNTIF('Recipe Ingredients'!$F$2:$F$2000,A15) | T15: Room temp until soft; fridge after | U15: 2-3 days ripe | V15: Southwest, South-south | W15: Wellness | X15: Seeds must be removed before blending.
A16: P015 | B16: Passion fruit | D16: Fruit | E16: Local + imported | F16: Recipe ingredient | G16: Seasonal | H16: Jan-Mar, May-Jun, Aug-Nov | J16: =IFERROR(IF(INDEX('Seasonal Calendar'!$C$2:$N$500,MATCH(A16,'Seasonal Calendar'!$A$2:$A$500,0),MONTH(TODAY()))="","Out",INDEX('Seasonal Calendar'!$C$2:$N$500,MATCH(A16,'Seasonal Calendar'!$A$2:$A$500,0),MONTH(TODAY()))),"") | K16: Sourced | L16: Pack of 4 | M16: 40000 | N16: 1kg imported | O16: The Fresh Place (thefreshplace.ng), 17 Oct 2026; listed out of stock | Q16: N | R16: Premium | S16: =COUNTIF('Recipe Ingredients'!$F$2:$F$2000,A16) | T16: Room temp; fridge when wrinkled | U16: 1-2 weeks | V16: Plateau | W16: Wellness | X16: Local supply exists (Plateau). Imported is very expensive, so source locally.
A17: P016 | B17: Coconut | C17: Agbon (Yor), Kwakwa (Hau) | D17: Fruit | E17: Local | F17: Eat as-is + recipes | G17: Year-round | H17: All year | J17: =IFERROR(IF(INDEX('Seasonal Calendar'!$C$2:$N$500,MATCH(A17,'Seasonal Calendar'!$A$2:$A$500,0),MONTH(TODAY()))="","Out",INDEX('Seasonal Calendar'!$C$2:$N$500,MATCH(A17,'Seasonal Calendar'!$A$2:$A$500,0),MONTH(TODAY()))),"") | K17: Verify | L17: Piece | M17: 1500 | N17: 1 pc | O17: The Fresh Place (thefreshplace.ng), 17 Oct 2026 | Q17: Y | R17: Core | S17: =COUNTIF('Recipe Ingredients'!$F$2:$F$2000,A17) | T17: Room temp | U17: 2-3 weeks whole | V17: Lagos (Badagry), Ogun, Ondo coast | W17: Plant-based, Hydration | X17: Fresh coconut milk replaces canned in most recipes here.
A18: P017 | B18: Agbalumo (African star apple) | C18: Agbalumo (Yor), Udara (Igbo), 'cherry' (Lagos) | D18: Fruit | E18: Local | F18: Eat as-is only | G18: Seasonal | H18: Dec-May | I18: Jan-Mar | J18: =IFERROR(IF(INDEX('Seasonal Calendar'!$C$2:$N$500,MATCH(A18,'Seasonal Calendar'!$A$2:$A$500,0),MONTH(TODAY()))="","Out",INDEX('Seasonal Calendar'!$C$2:$N$500,MATCH(A18,'Seasonal Calendar'!$A$2:$A$500,0),MONTH(TODAY()))),"") | K18: Sourced | L18: Pack of 10 / 20 | Q18: Seasonal | R18: Seasonal drop | S18: =COUNTIF('Recipe Ingredients'!$F$2:$F$2000,A18) | T18: Room temp | U18: 3-5 days | V18: Southwest and Southeast forest zones | W18: Wellness | X18: Hero of the seasonal drop calendar. Wild-harvested, so grade by size and sell by count.
A19: P018 | B19: Cashew apple | C19: Kaju (Yor), Kanju (Hau) | D19: Fruit | E19: Local | F19: Eat as-is only | G19: Seasonal | H19: Feb-Mar | I19: Feb-Mar | J19: =IFERROR(IF(INDEX('Seasonal Calendar'!$C$2:$N$500,MATCH(A19,'Seasonal Calendar'!$A$2:$A$500,0),MONTH(TODAY()))="","Out",INDEX('Seasonal Calendar'!$C$2:$N$500,MATCH(A19,'Seasonal Calendar'!$A$2:$A$500,0),MONTH(TODAY()))),"") | K19: Sourced | L19: Pack | Q19: N | R19: Later | S19: =COUNTIF('Recipe Ingredients'!$F$2:$F$2000,A19) | T19: Fridge; bruises fast | U19: 1-2 days | V19: Kogi, Oyo, Enugu | W19: Wellness | X19: Very short shelf life. Test only.
A20: P019 | B20: Velvet tamarind | C20: Awin (Yor), Icheku (Igbo), Tsamiyar kurmi (Hau) | D20: Fruit | E20: Local | F20: Eat as-is only | G20: Seasonal | H20: Jan-May | I20: Feb-Mar | J20: =IFERROR(IF(INDEX('Seasonal Calendar'!$C$2:$N$500,MATCH(A20,'Seasonal Calendar'!$A$2:$A$500,0),MONTH(TODAY()))="","Out",INDEX('Seasonal Calendar'!$C$2:$N$500,MATCH(A20,'Seasonal Calendar'!$A$2:$A$500,0),MONTH(TODAY()))),"") | K20: Sourced | L20: Cup / 100g pack | Q20: Seasonal | R20: Seasonal drop | S20: =COUNTIF('Recipe Ingredients'!$F$2:$F$2000,A20) | T20: Dry, airtight | U20: Weeks | V20: Southwest, Southeast, North | W20: Snack | X20: Shelf-stable and nostalgic. Natural checkout add-on.
A21: P020 | B21: Hog plum | C21: Iyeye (Yor) | D21: Fruit | E21: Local | F21: Eat as-is only | G21: Seasonal | H21: Jul, Dec | I21: Jul | J21: =IFERROR(IF(INDEX('Seasonal Calendar'!$C$2:$N$500,MATCH(A21,'Seasonal Calendar'!$A$2:$A$500,0),MONTH(TODAY()))="","Out",INDEX('Seasonal Calendar'!$C$2:$N$500,MATCH(A21,'Seasonal Calendar'!$A$2:$A$500,0),MONTH(TODAY()))),"") | K21: Sourced | L21: Pack | Q21: N | R21: Later | S21: =COUNTIF('Recipe Ingredients'!$F$2:$F$2000,A21) | T21: Fridge | U21: 1-2 days | V21: Southwest | W21: Snack | X21: Very short season and shelf life.
A22: P021 | B22: Pepper fruit | C22: Mmimi (Igbo) | D22: Fruit | E22: Local | F22: Eat as-is only | G22: Seasonal | H22: Feb-May | J22: =IFERROR(IF(INDEX('Seasonal Calendar'!$C$2:$N$500,MATCH(A22,'Seasonal Calendar'!$A$2:$A$500,0),MONTH(TODAY()))="","Out",INDEX('Seasonal Calendar'!$C$2:$N$500,MATCH(A22,'Seasonal Calendar'!$A$2:$A$500,0),MONTH(TODAY()))),"") | K22: Sourced | L22: Cup | Q22: N | R22: Later | S22: =COUNTIF('Recipe Ingredients'!$F$2:$F$2000,A22) | T22: Room temp | U22: 3-5 days | V22: Southeast | W22: Snack
A23: P022 | B23: Monkey kola | C23: Ochicha (Igbo), Obi edun (Yor) | D23: Fruit | E23: Local | F23: Eat as-is only | G23: Seasonal | H23: May-Aug | J23: =IFERROR(IF(INDEX('Seasonal Calendar'!$C$2:$N$500,MATCH(A23,'Seasonal Calendar'!$A$2:$A$500,0),MONTH(TODAY()))="","Out",INDEX('Seasonal Calendar'!$C$2:$N$500,MATCH(A23,'Seasonal Calendar'!$A$2:$A$500,0),MONTH(TODAY()))),"") | K23: Sourced | L23: Pack | Q23: N | R23: Later | S23: =COUNTIF('Recipe Ingredients'!$F$2:$F$2000,A23) | T23: Room temp | U23: 3-5 days | V23: Southeast, Southwest | W23: Snack
A24: P023 | B24: African pear | C24: Ube (Igbo) | D24: Fruit | E24: Local | F24: Eat as-is only | G24: Seasonal | H24: May-Sep | I24: Jun-Aug | J24: =IFERROR(IF(INDEX('Seasonal Calendar'!$C$2:$N$500,MATCH(A24,'Seasonal Calendar'!$A$2:$A$500,0),MONTH(TODAY()))="","Out",INDEX('Seasonal Calendar'!$C$2:$N$500,MATCH(A24,'Seasonal Calendar'!$A$2:$A$500,0),MONTH(TODAY()))),"") | K24: Sourced | L24: Pack of 10 | Q24: Seasonal | R24: Seasonal drop | S24: =COUNTIF('Recipe Ingredients'!$F$2:$F$2000,A24) | T24: Room temp | U24: 2-3 days | V24: Southeast, South-south | W24: Snack | X24: Classic pairing with roasted corn. Bundle the two as a rainy season drop.
A25: P024 | B25: Tiger nut | C25: Ofio (Yor), Aki Hausa (Igbo), Aya (Hau) | D25: Nut / tuber | E25: Local | F25: Eat as-is + recipes | G25: Seasonal | H25: Nov-May, Jul-Sep | J25: =IFERROR(IF(INDEX('Seasonal Calendar'!$C$2:$N$500,MATCH(A25,'Seasonal Calendar'!$A$2:$A$500,0),MONTH(TODAY()))="","Out",INDEX('Seasonal Calendar'!$C$2:$N$500,MATCH(A25,'Seasonal Calendar'!$A$2:$A$500,0),MONTH(TODAY()))),"") | K25: Sourced | L25: Cup / 250g | Q25: Y | R25: Core | S25: =COUNTIF('Recipe Ingredients'!$F$2:$F$2000,A25) | T25: Dry, airtight | U25: Weeks dried | V25: Kano, Kaduna, Niger | W25: Plant-based, Gut health | X25: Snack on its own or blend into kunun aya / horchata.
A26: P025 | B26: Sugarcane | C26: Ireke (Yor), Okpete (Igbo), Rake (Hau) | D26: Fruit (cane) | E26: Local | F26: Eat as-is only | G26: Seasonal | H26: Aug-Mar | J26: =IFERROR(IF(INDEX('Seasonal Calendar'!$C$2:$N$500,MATCH(A26,'Seasonal Calendar'!$A$2:$A$500,0),MONTH(TODAY()))="","Out",INDEX('Seasonal Calendar'!$C$2:$N$500,MATCH(A26,'Seasonal Calendar'!$A$2:$A$500,0),MONTH(TODAY()))),"") | K26: Sourced | L26: Stick / pre-cut pack | Q26: Seasonal | R26: Seasonal drop | S26: =COUNTIF('Recipe Ingredients'!$F$2:$F$2000,A26) | T26: Room temp; cut pieces in fridge | U26: 3-5 days | V26: North, Southwest | W26: Snack | X26: Pre-cut, peeled pieces are the only realistic delivery format.
A27: P026 | B27: Custard apple (sweetsop) | D27: Fruit | E27: Local | F27: Eat as-is only | G27: Seasonal | H27: Feb, Aug-Sep | J27: =IFERROR(IF(INDEX('Seasonal Calendar'!$C$2:$N$500,MATCH(A27,'Seasonal Calendar'!$A$2:$A$500,0),MONTH(TODAY()))="","Out",INDEX('Seasonal Calendar'!$C$2:$N$500,MATCH(A27,'Seasonal Calendar'!$A$2:$A$500,0),MONTH(TODAY()))),"") | K27: Sourced | L27: Piece | Q27: N | R27: Later | S27: =COUNTIF('Recipe Ingredients'!$F$2:$F$2000,A27) | T27: Room temp until soft | U27: 1-2 days ripe | V27: Southwest | W27: Snack
A28: P027 | B28: Jackfruit | D28: Fruit | E28: Local | F28: Eat as-is + recipes | G28: Seasonal | H28: May-Jun | I28: May | J28: =IFERROR(IF(INDEX('Seasonal Calendar'!$C$2:$N$500,MATCH(A28,'Seasonal Calendar'!$A$2:$A$500,0),MONTH(TODAY()))="","Out",INDEX('Seasonal Calendar'!$C$2:$N$500,MATCH(A28,'Seasonal Calendar'!$A$2:$A$500,0),MONTH(TODAY()))),"") | K28: Sourced | L28: Pre-cut pods | Q28: N | R28: Later | S28: =COUNTIF('Recipe Ingredients'!$F$2:$F$2000,A28) | T28: Fridge once cut | U28: 2-3 days cut | V28: South | W28: Snack | X28: Sell as cleaned pods, never whole.
A29: P028 | B29: June plum | D29: Fruit | E29: Local | F29: Eat as-is only | G29: Seasonal | H29: Dec-Jan | J29: =IFERROR(IF(INDEX('Seasonal Calendar'!$C$2:$N$500,MATCH(A29,'Seasonal Calendar'!$A$2:$A$500,0),MONTH(TODAY()))="","Out",INDEX('Seasonal Calendar'!$C$2:$N$500,MATCH(A29,'Seasonal Calendar'!$A$2:$A$500,0),MONTH(TODAY()))),"") | K29: Sourced | L29: Pack | Q29: N | R29: Later | S29: =COUNTIF('Recipe Ingredients'!$F$2:$F$2000,A29) | T29: Room temp | U29: 3-5 days | V29: South | W29: Snack
A30: P029 | B30: Sweet melon (golden / cantaloupe) | D30: Fruit | E30: Local + imported | F30: Eat as-is + recipes | G30: Year-round | H30: All year | I30: Jan, May-Jun | J30: =IFERROR(IF(INDEX('Seasonal Calendar'!$C$2:$N$500,MATCH(A30,'Seasonal Calendar'!$A$2:$A$500,0),MONTH(TODAY()))="","Out",INDEX('Seasonal Calendar'!$C$2:$N$500,MATCH(A30,'Seasonal Calendar'!$A$2:$A$500,0),MONTH(TODAY()))),"") | K30: Sourced | L30: Piece | M30: 15950 | N30: 1 imported galia | O30: Mint Foods (mintfoods.store), 11 Oct 2026 | Q30: N | R30: Premium | S30: =COUNTIF('Recipe Ingredients'!$F$2:$F$2000,A30) | T30: Room temp to ripen; fridge cut | U30: 3-5 days ripe | V30: North | W30: Hydration | X30: Local golden melon in Jan and May-Jun; imported the rest of the year at a high price.
A31: P030 | B31: Dates | C31: Dabino (Hau) | D31: Fruit | E31: Local + imported | F31: Eat as-is + recipes | G31: Year-round | H31: All year | I31: Apr-Jul | J31: =IFERROR(IF(INDEX('Seasonal Calendar'!$C$2:$N$500,MATCH(A31,'Seasonal Calendar'!$A$2:$A$500,0),MONTH(TODAY()))="","Out",INDEX('Seasonal Calendar'!$C$2:$N$500,MATCH(A31,'Seasonal Calendar'!$A$2:$A$500,0),MONTH(TODAY()))),"") | K31: Sourced | L31: 250g pack | M31: 5200 | N31: 1 pack (size not stated) | O31: The Fresh Place (thefreshplace.ng), 17 Oct 2026; listed out of stock | Q31: Y | R31: Core | S31: =COUNTIF('Recipe Ingredients'!$F$2:$F$2000,A31) | T31: Airtight, cool | U31: Months dried | V31: North (Borno, Yobe) + imports | W31: Training, Energy | X31: Fresh dates Apr-Jul; dried all year. Used as the natural sweetener across the library.
A32: P031 | B32: Apple (red & green) | D32: Fruit | E32: Imported | F32: Eat as-is + recipes | G32: Year-round | H32: All year | J32: =IFERROR(IF(INDEX('Seasonal Calendar'!$C$2:$N$500,MATCH(A32,'Seasonal Calendar'!$A$2:$A$500,0),MONTH(TODAY()))="","Out",INDEX('Seasonal Calendar'!$C$2:$N$500,MATCH(A32,'Seasonal Calendar'!$A$2:$A$500,0),MONTH(TODAY()))),"") | K32: Verify | L32: Piece / 6-pack | M32: 500 | N32: 1 pc small (Granny Smith) | O32: The Fresh Place (thefreshplace.ng), 17 Oct 2026; Golden Delicious N450/pc; Pink Lady big N800/pc; small Granny Smith dozen N5,400 | Q32: Y | R32: Core (imported) | S32: =COUNTIF('Recipe Ingredients'!$F$2:$F$2000,A32) | T32: Fridge | U32: 2-4 weeks | V32: Imported (South Africa, EU) | W32: Weight management | X32: Imported, but a basket expectation in Lagos. Every competitor bundle includes it.
A33: P032 | B33: Pear | D33: Fruit | E33: Imported | F33: Eat as-is + recipes | G33: Year-round | H33: All year | J33: =IFERROR(IF(INDEX('Seasonal Calendar'!$C$2:$N$500,MATCH(A33,'Seasonal Calendar'!$A$2:$A$500,0),MONTH(TODAY()))="","Out",INDEX('Seasonal Calendar'!$C$2:$N$500,MATCH(A33,'Seasonal Calendar'!$A$2:$A$500,0),MONTH(TODAY()))),"") | K33: Verify | L33: Piece | M33: 700 | N33: 1 pc (English pear) | O33: The Fresh Place (thefreshplace.ng), 17 Oct 2026 | Q33: N | R33: Premium | S33: =COUNTIF('Recipe Ingredients'!$F$2:$F$2000,A33) | T33: Fridge once ripe | U33: 1-2 weeks | V33: Imported | W33: Weight management | X33: Included in The Fresh Place bundles (10 English pears).
A34: P033 | B34: Grapes (red / black seedless) | D34: Fruit | E34: Imported | F34: Eat as-is + recipes | G34: Year-round | H34: All year | J34: =IFERROR(IF(INDEX('Seasonal Calendar'!$C$2:$N$500,MATCH(A34,'Seasonal Calendar'!$A$2:$A$500,0),MONTH(TODAY()))="","Out",INDEX('Seasonal Calendar'!$C$2:$N$500,MATCH(A34,'Seasonal Calendar'!$A$2:$A$500,0),MONTH(TODAY()))),"") | K34: Verify | L34: 500g | M34: 7000 | N34: 1 pack, red or green seedless (size not stated) | O34: The Fresh Place (thefreshplace.ng), 17 Oct 2026; black seedless N7,500, listed out of stock | Q34: N | R34: Premium | S34: =COUNTIF('Recipe Ingredients'!$F$2:$F$2000,A34) | T34: Fridge, unwashed | U34: 5-7 days | V34: Imported | W34: Snack
A35: P034 | B35: Strawberry | D35: Fruit (berry) | E35: Local + imported | F35: Eat as-is + recipes | G35: Seasonal | H35: Nov-Apr | I35: Dec-Feb | J35: =IFERROR(IF(INDEX('Seasonal Calendar'!$C$2:$N$500,MATCH(A35,'Seasonal Calendar'!$A$2:$A$500,0),MONTH(TODAY()))="","Out",INDEX('Seasonal Calendar'!$C$2:$N$500,MATCH(A35,'Seasonal Calendar'!$A$2:$A$500,0),MONTH(TODAY()))),"") | K35: Verify | L35: 250g punnet | M35: 5000 | N35: 1 pack (size not stated) | O35: The Fresh Place (thefreshplace.ng), 17 Oct 2026 | Q35: N | R35: Premium | S35: =COUNTIF('Recipe Ingredients'!$F$2:$F$2000,A35) | T35: Fridge, unwashed | U35: 2-4 days | V35: Plateau (Jos) + imports | W35: Wellness | X35: Jos strawberries are a real local story. Season window needs supplier confirmation.
A36: P035 | B36: Blueberry | D36: Fruit (berry) | E36: Imported | F36: Eat as-is + recipes | G36: Year-round | H36: All year | J36: =IFERROR(IF(INDEX('Seasonal Calendar'!$C$2:$N$500,MATCH(A36,'Seasonal Calendar'!$A$2:$A$500,0),MONTH(TODAY()))="","Out",INDEX('Seasonal Calendar'!$C$2:$N$500,MATCH(A36,'Seasonal Calendar'!$A$2:$A$500,0),MONTH(TODAY()))),"") | K36: Verify | L36: 125g | M36: 6000 | N36: 1 pack (size not stated) | O36: The Fresh Place (thefreshplace.ng), 17 Oct 2026 | Q36: N | R36: Premium | S36: =COUNTIF('Recipe Ingredients'!$F$2:$F$2000,A36) | T36: Fridge | U36: 5-7 days | V36: Imported | W36: Wellness
A37: P036 | B37: Kiwi | D37: Fruit | E37: Imported | F37: Eat as-is + recipes | G37: Year-round | H37: All year | J37: =IFERROR(IF(INDEX('Seasonal Calendar'!$C$2:$N$500,MATCH(A37,'Seasonal Calendar'!$A$2:$A$500,0),MONTH(TODAY()))="","Out",INDEX('Seasonal Calendar'!$C$2:$N$500,MATCH(A37,'Seasonal Calendar'!$A$2:$A$500,0),MONTH(TODAY()))),"") | K37: Verify | L37: 3-pack | M37: 20000 | N37: 1kg | O37: The Fresh Place (thefreshplace.ng), 17 Oct 2026 | Q37: N | R37: Premium | S37: =COUNTIF('Recipe Ingredients'!$F$2:$F$2000,A37) | T37: Fridge | U37: 1-2 weeks | V37: Imported | W37: Wellness
A38: P037 | B38: Pomegranate | D38: Fruit | E38: Imported | F38: Eat as-is + recipes | G38: Year-round | H38: All year | J38: =IFERROR(IF(INDEX('Seasonal Calendar'!$C$2:$N$500,MATCH(A38,'Seasonal Calendar'!$A$2:$A$500,0),MONTH(TODAY()))="","Out",INDEX('Seasonal Calendar'!$C$2:$N$500,MATCH(A38,'Seasonal Calendar'!$A$2:$A$500,0),MONTH(TODAY()))),"") | K38: Verify | L38: Piece | M38: 18000 | N38: 1kg | O38: The Fresh Place (thefreshplace.ng), 17 Oct 2026; listed out of stock | Q38: N | R38: Later | S38: =COUNTIF('Recipe Ingredients'!$F$2:$F$2000,A38) | T38: Fridge | U38: 2-3 weeks | V38: Imported | W38: Wellness
A39: P038 | B39: Dragon fruit | D39: Fruit | E39: Local (limited) + imported | F39: Eat as-is + recipes | G39: Year-round | H39: All year | J39: =IFERROR(IF(INDEX('Seasonal Calendar'!$C$2:$N$500,MATCH(A39,'Seasonal Calendar'!$A$2:$A$500,0),MONTH(TODAY()))="","Out",INDEX('Seasonal Calendar'!$C$2:$N$500,MATCH(A39,'Seasonal Calendar'!$A$2:$A$500,0),MONTH(TODAY()))),"") | K39: Verify | L39: Piece | M39: 40000 | N39: 1kg | O39: The Fresh Place (thefreshplace.ng), 17 Oct 2026; listed out of stock | Q39: N | R39: Later | S39: =COUNTIF('Recipe Ingredients'!$F$2:$F$2000,A39) | T39: Fridge | U39: 5-7 days | V39: A few local farms + imports | W39: Wellness | X39: Price makes it a showpiece, not a staple.
A40: P039 | B40: Star fruit (carambola) | D40: Fruit | E40: Local | F40: Eat as-is + recipes | G40: Year-round | H40: All year | J40: =IFERROR(IF(INDEX('Seasonal Calendar'!$C$2:$N$500,MATCH(A40,'Seasonal Calendar'!$A$2:$A$500,0),MONTH(TODAY()))="","Out",INDEX('Seasonal Calendar'!$C$2:$N$500,MATCH(A40,'Seasonal Calendar'!$A$2:$A$500,0),MONTH(TODAY()))),"") | K40: Verify | L40: Piece | Q40: N | R40: Later | S40: =COUNTIF('Recipe Ingredients'!$F$2:$F$2000,A40) | T40: Room temp / fridge | U40: 3-5 days | V40: South | W40: Snack | X40: Availability is patchy. Verify with suppliers.
...

Sheet Seasonal Calendar
A1: ID | B1: Produce | C1: Jan | D1: Feb | E1: Mar | F1: Apr | G1: May | H1: Jun | I1: Jul | J1: Aug | K1: Sep | L1: Oct | M1: Nov | N1: Dec | O1: Months available | P1: Role
A2: P001 | B2: Banana | C2: In | D2: In | E2: In | F2: In | G2: In | H2: In | I2: In | J2: In | K2: In | L2: In | M2: In | N2: In | O2: =COUNTIF(C2:N2,"Peak")+COUNTIF(C2:N2,"In") | P2: Eat as-is + recipes
A3: P002 | B3: Plantain (ripe & unripe) | C3: In | D3: In | E3: In | F3: In | G3: In | H3: In | I3: In | J3: In | K3: In | L3: In | M3: In | N3: In | O3: =COUNTIF(C3:N3,"Peak")+COUNTIF(C3:N3,"In") | P3: Recipe ingredient
A4: P003 | B4: Pineapple | C4: In | D4: In | E4: In | F4: In | G4: In | H4: In | I4: In | J4: In | K4: In | L4: In | M4: In | N4: In | O4: =COUNTIF(C4:N4,"Peak")+COUNTIF(C4:N4,"In") | P4: Eat as-is + recipes
A5: P004 | B5: Watermelon | C5: Peak | D5: Peak | E5: Peak | F5: Peak | G5: In | H5: In | I5: In | J5: In | K5: In | L5: In | M5: In | N5: Peak | O5: =COUNTIF(C5:N5,"Peak")+COUNTIF(C5:N5,"In") | P5: Eat as-is + recipes
A6: P005 | B6: Pawpaw (papaya) | C6: In | D6: In | E6: In | F6: In | G6: In | H6: In | I6: In | J6: In | K6: In | L6: In | M6: In | N6: In | O6: =COUNTIF(C6:N6,"Peak")+COUNTIF(C6:N6,"In") | P6: Eat as-is + recipes
A7: P006 | B7: Mango | D7: In | E7: Peak | F7: Peak | G7: In | J7: In | K7: In | O7: =COUNTIF(C7:N7,"Peak")+COUNTIF(C7:N7,"In") | P7: Eat as-is + recipes
A8: P007 | B8: Orange | C8: Peak | D8: In | E8: In | F8: In | G8: In | H8: In | I8: In | J8: In | K8: In | L8: Peak | M8: Peak | N8: Peak | O8: =COUNTIF(C8:N8,"Peak")+COUNTIF(C8:N8,"In") | P8: Eat as-is + recipes
A9: P008 | B9: Tangerine | C9: Peak | D9: In | E9: In | F9: In | G9: In | H9: In | I9: In | J9: In | K9: In | L9: Peak | M9: Peak | N9: Peak | O9: =COUNTIF(C9:N9,"Peak")+COUNTIF(C9:N9,"In") | P9: Eat as-is + recipes
A10: P009 | B10: Lemon | C10: Peak | D10: In | E10: In | F10: In | G10: In | H10: In | I10: In | J10: In | K10: In | L10: Peak | M10: Peak | N10: Peak | O10: =COUNTIF(C10:N10,"Peak")+COUNTIF(C10:N10,"In") | P10: Recipe ingredient
A11: P010 | B11: Lime | C11: Peak | D11: In | E11: In | F11: In | G11: In | H11: In | I11: In | J11: In | K11: In | L11: Peak | M11: Peak | N11: Peak | O11: =COUNTIF(C11:N11,"Peak")+COUNTIF(C11:N11,"In") | P11: Recipe ingredient
A12: P011 | B12: Grapefruit | C12: Peak | D12: In | E12: In | F12: In | G12: In | H12: In | I12: In | J12: In | K12: In | L12: Peak | M12: Peak | N12: Peak | O12: =COUNTIF(C12:N12,"Peak")+COUNTIF(C12:N12,"In") | P12: Eat as-is + recipes
A13: P012 | B13: Avocado | C13: In | D13: In | E13: In | F13: In | G13: In | H13: In | I13: In | J13: In | K13: In | L13: In | M13: In | N13: In | O13: =COUNTIF(C13:N13,"Peak")+COUNTIF(C13:N13,"In") | P13: Eat as-is + recipes
A14: P013 | B14: Guava | D14: Peak | E14: Peak | J14: In | K14: In | O14: =COUNTIF(C14:N14,"Peak")+COUNTIF(C14:N14,"In") | P14: Eat as-is + recipes
A15: P014 | B15: Soursop | C15: In | D15: Peak | E15: Peak | G15: In | H15: In | I15: In | J15: In | L15: In | N15: In | O15: =COUNTIF(C15:N15,"Peak")+COUNTIF(C15:N15,"In") | P15: Eat as-is + recipes
A16: P015 | B16: Passion fruit | C16: In | D16: In | E16: In | G16: In | H16: In | J16: In | K16: In | L16: In | M16: In | O16: =COUNTIF(C16:N16,"Peak")+COUNTIF(C16:N16,"In") | P16: Recipe ingredient
A17: P016 | B17: Coconut | C17: In | D17: In | E17: In | F17: In | G17: In | H17: In | I17: In | J17: In | K17: In | L17: In | M17: In | N17: In | O17: =COUNTIF(C17:N17,"Peak")+COUNTIF(C17:N17,"In") | P17: Eat as-is + recipes
A18: P017 | B18: Agbalumo (African star apple) | C18: Peak | D18: Peak | E18: Peak | F18: In | G18: In | N18: In | O18: =COUNTIF(C18:N18,"Peak")+COUNTIF(C18:N18,"In") | P18: Eat as-is only
A19: P018 | B19: Cashew apple | D19: Peak | E19: Peak | O19: =COUNTIF(C19:N19,"Peak")+COUNTIF(C19:N19,"In") | P19: Eat as-is only
A20: P019 | B20: Velvet tamarind | C20: In | D20: Peak | E20: Peak | F20: In | G20: In | O20: =COUNTIF(C20:N20,"Peak")+COUNTIF(C20:N20,"In") | P20: Eat as-is only
A21: P020 | B21: Hog plum | I21: Peak | N21: In | O21: =COUNTIF(C21:N21,"Peak")+COUNTIF(C21:N21,"In") | P21: Eat as-is only
A22: P021 | B22: Pepper fruit | D22: In | E22: In | F22: In | G22: In | O22: =COUNTIF(C22:N22,"Peak")+COUNTIF(C22:N22,"In") | P22: Eat as-is only
A23: P022 | B23: Monkey kola | G23: In | H23: In | I23: In | J23: In | O23: =COUNTIF(C23:N23,"Peak")+COUNTIF(C23:N23,"In") | P23: Eat as-is only
A24: P023 | B24: African pear | G24: In | H24: Peak | I24: Peak | J24: Peak | K24: In | O24: =COUNTIF(C24:N24,"Peak")+COUNTIF(C24:N24,"In") | P24: Eat as-is only
A25: P024 | B25: Tiger nut | C25: In | D25: In | E25: In | F25: In | G25: In | I25: In | J25: In | K25: In | M25: In | N25: In | O25: =COUNTIF(C25:N25,"Peak")+COUNTIF(C25:N25,"In") | P25: Eat as-is + recipes
A26: P025 | B26: Sugarcane | C26: In | D26: In | E26: In | J26: In | K26: In | L26: In | M26: In | N26: In | O26: =COUNTIF(C26:N26,"Peak")+COUNTIF(C26:N26,"In") | P26: Eat as-is only
A27: P026 | B27: Custard apple (sweetsop) | D27: In | J27: In | K27: In | O27: =COUNTIF(C27:N27,"Peak")+COUNTIF(C27:N27,"In") | P27: Eat as-is only
A28: P027 | B28: Jackfruit | G28: Peak | H28: In | O28: =COUNTIF(C28:N28,"Peak")+COUNTIF(C28:N28,"In") | P28: Eat as-is + recipes
A29: P028 | B29: June plum | C29: In | N29: In | O29: =COUNTIF(C29:N29,"Peak")+COUNTIF(C29:N29,"In") | P29: Eat as-is only
A30: P029 | B30: Sweet melon (golden / cantaloupe) | C30: Peak | D30: In | E30: In | F30: In | G30: Peak | H30: Peak | I30: In | J30: In | K30: In | L30: In | M30: In | N30: In | O30: =COUNTIF(C30:N30,"Peak")+COUNTIF(C30:N30,"In") | P30: Eat as-is + recipes
A31: P030 | B31: Dates | C31: In | D31: In | E31: In | F31: Peak | G31: Peak | H31: Peak | I31: Peak | J31: In | K31: In | L31: In | M31: In | N31: In | O31: =COUNTIF(C31:N31,"Peak")+COUNTIF(C31:N31,"In") | P31: Eat as-is + recipes
A32: P031 | B32: Apple (red & green) | C32: In | D32: In | E32: In | F32: In | G32: In | H32: In | I32: In | J32: In | K32: In | L32: In | M32: In | N32: In | O32: =COUNTIF(C32:N32,"Peak")+COUNTIF(C32:N32,"In") | P32: Eat as-is + recipes
A33: P032 | B33: Pear | C33: In | D33: In | E33: In | F33: In | G33: In | H33: In | I33: In | J33: In | K33: In | L33: In | M33: In | N33: In | O33: =COUNTIF(C33:N33,"Peak")+COUNTIF(C33:N33,"In") | P33: Eat as-is + recipes
A34: P033 | B34: Grapes (red / black seedless) | C34: In | D34: In | E34: In | F34: In | G34: In | H34: In | I34: In | J34: In | K34: In | L34: In | M34: In | N34: In | O34: =COUNTIF(C34:N34,"Peak")+COUNTIF(C34:N34,"In") | P34: Eat as-is + recipes
A35: P034 | B35: Strawberry | C35: Peak | D35: Peak | E35: In | F35: In | M35: In | N35: Peak | O35: =COUNTIF(C35:N35,"Peak")+COUNTIF(C35:N35,"In") | P35: Eat as-is + recipes
A36: P035 | B36: Blueberry | C36: In | D36: In | E36: In | F36: In | G36: In | H36: In | I36: In | J36: In | K36: In | L36: In | M36: In | N36: In | O36: =COUNTIF(C36:N36,"Peak")+COUNTIF(C36:N36,"In") | P36: Eat as-is + recipes
A37: P036 | B37: Kiwi | C37: In | D37: In | E37: In | F37: In | G37: In | H37: In | I37: In | J37: In | K37: In | L37: In | M37: In | N37: In | O37: =COUNTIF(C37:N37,"Peak")+COUNTIF(C37:N37,"In") | P37: Eat as-is + recipes
A38: P037 | B38: Pomegranate | C38: In | D38: In | E38: In | F38: In | G38: In | H38: In | I38: In | J38: In | K38: In | L38: In | M38: In | N38: In | O38: =COUNTIF(C38:N38,"Peak")+COUNTIF(C38:N38,"In") | P38: Eat as-is + recipes
A39: P038 | B39: Dragon fruit | C39: In | D39: In | E39: In | F39: In | G39: In | H39: In | I39: In | J39: In | K39: In | L39: In | M39: In | N39: In | O39: =COUNTIF(C39:N39,"Peak")+COUNTIF(C39:N39,"In") | P39: Eat as-is + recipes
A40: P039 | B40: Star fruit (carambola) | C40: In | D40: In | E40: In | F40: In | G40: In | H40: In | I40: In | J40: In | K40: In | L40: In | M40: In | N40: In | O40: =COUNTIF(C40:N40,"Peak")+COUNTIF(C40:N40,"In") | P40: Eat as-is + recipes
...

Sheet Recipes
A1: ID | B1: Recipe | C1: Category | D1: Meal | E1: Inspired by | F1: Local adaptation | G1: Goal tags | H1: Diet | I1: Prep (min) | J1: Cook (min) | K1: Total (min) | L1: Effort tier | M1: Servings | N1: Est. kcal / serving | O1: Est. protein (g) / serving | P1: Hero produce | Q1: Basket items | R1: Other items | S1: Basket coverage | T1: Hits target? | U1: Seasonal ingredients | V1: Method | W1: Tip | X1: Status
A2: R015 | B2: Mango & Passion Fruit Overnight Oats | C2: Breakfast | D2: Breakfast | E2: Bircher muesli (Switzerland) / overnight oats | F2: Mango and passion fruit on top, tiger nut milk as an option. | G2: Training, Weight management | H2: Vegetarian | I2: 10 | J2: 0 | K2: =I2+J2 | L2: =IF(J2=0,"No-cook",IF(K2<=25,"Quick","Standard")) | M2: 2 | N2: 380 | O2: 14 | P2: Mango, Passion fruit | Q2: =COUNTIFS('Recipe Ingredients'!$A$2:$A$2000,A2,'Recipe Ingredients'!$G$2:$G$2000,"Basket") | R2: =COUNTIFS('Recipe Ingredients'!$A$2:$A$2000,A2,'Recipe Ingredients'!$G$2:$G$2000,"Protein")+COUNTIFS('Recipe Ingredients'!$A$2:$A$2000,A2,'Recipe Ingredients'!$G$2:$G$2000,"Pantry") | S2: =IFERROR(Q2/(Q2+R2),0) | T2: =IF(S2>='Start Here'!$C$6,"Yes","No") | U2: Mango (Feb-May, Aug-Sep); Passion fruit (Jan-Mar, May-Jun, Aug-Nov) | V2: 1. Stir oats, milk, yoghurt and chia together in two jars. 2. Cover and refrigerate overnight. 3. In the morning, top with diced mango and passion fruit pulp. 4. Drizzle with honey if you like. | W2: Make 3 days at once for a week of grab-and-go breakfasts. | X2: Draft
A3: R016 | B3: Pawpaw Boats with Yoghurt & Groundnut Crunch | C3: Breakfast | D3: Breakfast | E3: Papaya boats (Hawaii / Bali brunch spots) | F3: Crushed groundnuts and pineapple replace imported berries. | G3: Weight management, Wellness | H3: Vegetarian | I3: 5 | J3: 0 | K3: =I3+J3 | L3: =IF(J3=0,"No-cook",IF(K3<=25,"Quick","Standard")) | M3: 2 | N3: 320 | O3: 12 | P3: Pawpaw, Pineapple, Lime, Groundnut | Q3: =COUNTIFS('Recipe Ingredients'!$A$2:$A$2000,A3,'Recipe Ingredients'!$G$2:$G$2000,"Basket") | R3: =COUNTIFS('Recipe Ingredients'!$A$2:$A$2000,A3,'Recipe Ingredients'!$G$2:$G$2000,"Protein")+COUNTIFS('Recipe Ingredients'!$A$2:$A$2000,A3,'Recipe Ingredients'!$G$2:$G$2000,"Pantry") | S3: =IFERROR(Q3/(Q3+R3),0) | T3: =IF(S3>='Start Here'!$C$6,"Yes","No") | U3: Year-round | V3: 1. Halve the pawpaw lengthways and scoop out the seeds. 2. Fill each half with yoghurt. 3. Top with granola, pineapple and crushed groundnuts. 4. Finish with lime zest and a drizzle of honey. | X3: Draft
A4: R017 | B4: Banana Oat Pancakes with Pineapple Compote | C4: Breakfast | D4: Breakfast | E4: Three-ingredient banana pancakes (US fitness) | F4: Warm pineapple compote stands in for maple syrup and berries. | G4: Training | H4: Vegetarian | I4: 10 | J4: 15 | K4: =I4+J4 | L4: =IF(J4=0,"No-cook",IF(K4<=25,"Quick","Standard")) | M4: 2 | N4: 360 | O4: 15 | P4: Banana, Pineapple, Lime | Q4: =COUNTIFS('Recipe Ingredients'!$A$2:$A$2000,A4,'Recipe Ingredients'!$G$2:$G$2000,"Basket") | R4: =COUNTIFS('Recipe Ingredients'!$A$2:$A$2000,A4,'Recipe Ingredients'!$G$2:$G$2000,"Protein")+COUNTIFS('Recipe Ingredients'!$A$2:$A$2000,A4,'Recipe Ingredients'!$G$2:$G$2000,"Pantry") | S4: =IFERROR(Q4/(Q4+R4),0) | T4: =IF(S4>='Start Here'!$C$6,"Yes","No") | U4: Year-round | V4: 1. Blend bananas, eggs, oats and cinnamon into a thick batter. 2. Cook small pancakes in a lightly oiled pan, 2 minutes a side. 3. Simmer pineapple with lime juice for 5 minutes until jammy. 4. Stack the pancakes and spoon the compote over. | X4: Draft
A5: R018 | B5: Shakshuka with Tatashe & Efo | C5: Breakfast | D5: Brunch | E5: Shakshuka (North Africa / Middle East) | F5: The sauce is basically a lighter obe ata. Greens folded in at the end. | G5: Training, Weight management | H5: Vegetarian | I5: 10 | J5: 20 | K5: =I5+J5 | L5: =IF(J5=0,"No-cook",IF(K5<=25,"Quick","Standard")) | M5: 2 | N5: 330 | O5: 17 | P5: Tomato, Red bell pepper, Scotch bonnet, Onion | Q5: =COUNTIFS('Recipe Ingredients'!$A$2:$A$2000,A5,'Recipe Ingredients'!$G$2:$G$2000,"Basket") | R5: =COUNTIFS('Recipe Ingredients'!$A$2:$A$2000,A5,'Recipe Ingredients'!$G$2:$G$2000,"Protein")+COUNTIFS('Recipe Ingredients'!$A$2:$A$2000,A5,'Recipe Ingredients'!$G$2:$G$2000,"Pantry") | S5: =IFERROR(Q5/(Q5+R5),0) | T5: =IF(S5>='Start Here'!$C$6,"Yes","No") | U5: Year-round | V5: 1. Soften chopped onion and garlic in oil. 2. Add chopped tomatoes, tatashe, ata rodo and cumin. Simmer 10 minutes until thick. 3. Stir in the efo tete, then make four wells and crack in the eggs. 4. Cover and cook 5 to 6 minutes until the whites set. Serve with bread. | X5: Draft
A6: R019 | B6: Avocado Toast with Ata Rodo Salsa | C6: Breakfast | D6: Breakfast | E6: Avocado toast (Australian cafe culture) | F6: A fresh tomato, onion and ata rodo salsa on top instead of chilli flakes. | G6: Wellness, Weight management | H6: Vegetarian | I6: 10 | J6: 3 | K6: =I6+J6 | L6: =IF(J6=0,"No-cook",IF(K6<=25,"Quick","Standard")) | M6: 2 | N6: 380 | O6: 13 | P6: Avocado, Tomato, Onion, Scotch bonnet | Q6: =COUNTIFS('Recipe Ingredients'!$A$2:$A$2000,A6,'Recipe Ingredients'!$G$2:$G$2000,"Basket") | R6: =COUNTIFS('Recipe Ingredients'!$A$2:$A$2000,A6,'Recipe Ingredients'!$G$2:$G$2000,"Protein")+COUNTIFS('Recipe Ingredients'!$A$2:$A$2000,A6,'Recipe Ingredients'!$G$2:$G$2000,"Pantry") | S6: =IFERROR(Q6/(Q6+R6),0) | T6: =IF(S6>='Start Here'!$C$6,"Yes","No") | U6: Year-round | V6: 1. Toast the bread. 2. Mash avocado with half the lime juice and a pinch of salt. 3. Dice tomato, onion and ata rodo and toss with the rest of the lime. 4. Spread avocado, spoon over salsa, top with sliced boiled egg if using. | X6: Draft
A7: R020 | B7: Sweet Potato Breakfast Hash | C7: Breakfast | D7: Breakfast | E7: American diner hash | F7: Sweet potato is cheaper locally than Irish potato and keeps you full longer. | G7: Training | H7: Vegetarian | I7: 10 | J7: 20 | K7: =I7+J7 | L7: =IF(J7=0,"No-cook",IF(K7<=25,"Quick","Standard")) | M7: 2 | N7: 420 | O7: 16 | P7: Sweet potato, Onion, Red bell pepper, Amaranth greens | Q7: =COUNTIFS('Recipe Ingredients'!$A$2:$A$2000,A7,'Recipe Ingredients'!$G$2:$G$2000,"Basket") | R7: =COUNTIFS('Recipe Ingredients'!$A$2:$A$2000,A7,'Recipe Ingredients'!$G$2:$G$2000,"Protein")+COUNTIFS('Recipe Ingredients'!$A$2:$A$2000,A7,'Recipe Ingredients'!$G$2:$G$2000,"Pantry") | S7: =IFERROR(Q7/(Q7+R7),0) | T7: =IF(S7>='Start Here'!$C$6,"Yes","No") | U7: Year-round | V7: 1. Dice sweet potatoes small and fry in oil for 10 minutes until golden. 2. Add onion and tatashe, cook 4 minutes. Season with paprika and salt. 3. Stir in efo tete until wilted. 4. Make wells, crack in eggs, cover until set. Finish with spring onion. | X7: Draft
A8: R021 | B8: Plantain & Efo Frittata | C8: Breakfast | D8: Breakfast / Lunch | E8: Spanish tortilla / Italian frittata | F8: Ripe plantain takes the place of potato. Dodo meets tortilla. | G8: Training | H8: Vegetarian | I8: 10 | J8: 20 | K8: =I8+J8 | L8: =IF(J8=0,"No-cook",IF(K8<=25,"Quick","Standard")) | M8: 3 | N8: 350 | O8: 15 | P8: Plantain, Amaranth greens, Onion, Red bell pepper | Q8: =COUNTIFS('Recipe Ingredients'!$A$2:$A$2000,A8,'Recipe Ingredients'!$G$2:$G$2000,"Basket") | R8: =COUNTIFS('Recipe Ingredients'!$A$2:$A$2000,A8,'Recipe Ingredients'!$G$2:$G$2000,"Protein")+COUNTIFS('Recipe Ingredients'!$A$2:$A$2000,A8,'Recipe Ingredients'!$G$2:$G$2000,"Pantry") | S8: =IFERROR(Q8/(Q8+R8),0) | T8: =IF(S8>='Start Here'!$C$6,"Yes","No") | U8: Year-round | V8: 1. Slice the plantain and fry until golden on both sides. 2. Add onion, tatashe and ata rodo, cook 3 minutes, then the efo. 3. Pour over beaten, seasoned eggs. 4. Cook on low with a lid until set, about 8 minutes. Slice like a cake. | W8: Cold slices travel well in a lunch box. | X8: Draft
A9: R022 | B9: Tropical Parfait with Tiger Nut Crumble | C9: Breakfast | D9: Breakfast / Snack | E9: Yoghurt parfait (France / US cafes) | F9: Tiger nut and coconut crumble replaces store-bought granola. | G9: Weight management, Wellness | H9: Vegetarian | I9: 10 | J9: 0 | K9: =I9+J9 | L9: =IF(J9=0,"No-cook",IF(K9<=25,"Quick","Standard")) | M9: 2 | N9: 340 | O9: 14 | P9: Pineapple, Banana, Mango, Tiger nut | Q9: =COUNTIFS('Recipe Ingredients'!$A$2:$A$2000,A9,'Recipe Ingredients'!$G$2:$G$2000,"Basket") | R9: =COUNTIFS('Recipe Ingredients'!$A$2:$A$2000,A9,'Recipe Ingredients'!$G$2:$G$2000,"Protein")+COUNTIFS('Recipe Ingredients'!$A$2:$A$2000,A9,'Recipe Ingredients'!$G$2:$G$2000,"Pantry") | S9: =IFERROR(Q9/(Q9+R9),0) | T9: =IF(S9>='Start Here'!$C$6,"Yes","No") | U9: Mango (Feb-May, Aug-Sep); Tiger nut (Nov-May, Jul-Sep) | V9: 1. Chop tiger nuts roughly and toast with grated coconut in a dry pan for 3 minutes. 2. Dice pineapple, banana and mango. 3. Layer yoghurt, fruit and crumble in two glasses. 4. Finish with honey. | W9: Off season, pawpaw replaces mango. | X9: Draft
A10: R023 | B10: Coconut Chia Pudding with Mango | C10: Breakfast | D10: Breakfast / Dessert | E10: Chia pudding (wellness cafes) | F10: Fresh coconut milk and dates instead of canned milk and maple syrup. | G10: Plant-based, Wellness | H10: Vegan | I10: 10 | J10: 0 | K10: =I10+J10 | L10: =IF(J10=0,"No-cook",IF(K10<=25,"Quick","Standard")) | M10: 2 | N10: 320 | O10: 7 | P10: Coconut, Dates, Mango, Lime | Q10: =COUNTIFS('Recipe Ingredients'!$A$2:$A$2000,A10,'Recipe Ingredients'!$G$2:$G$2000,"Basket") | R10: =COUNTIFS('Recipe Ingredients'!$A$2:$A$2000,A10,'Recipe Ingredients'!$G$2:$G$2000,"Protein")+COUNTIFS('Recipe Ingredients'!$A$2:$A$2000,A10,'Recipe Ingredients'!$G$2:$G$2000,"Pantry") | S10: =IFERROR(Q10/(Q10+R10),0) | T10: =IF(S10>='Start Here'!$C$6,"Yes","No") | U10: Mango (Feb-May, Aug-Sep) | V10: 1. Blend coconut flesh with warm water and dates, then strain to get sweet coconut milk. 2. Stir chia seeds into the milk and leave 10 minutes, then stir again. 3. Refrigerate at least 4 hours. 4. Top with diced mango and lime zest. | X10: Draft
A11: R024 | B11: Chilli-Lime Fruit Cup (Yaji Edition) | C11: Snack | D11: Snack | E11: Mexican fruit cup with chile and lime (Tajin) | F11: Yaji replaces Tajin. Same salty, spicy, sour hit on cold fruit. | G11: Hydration, Weight management | H11: Vegan | I11: 10 | J11: 0 | K11: =I11+J11 | L11: =IF(J11=0,"No-cook",IF(K11<=25,"Quick","Standard")) | M11: 2 | N11: 120 | O11: 2 | P11: Watermelon, Pineapple, Pawpaw, Cucumber | Q11: =COUNTIFS('Recipe Ingredients'!$A$2:$A$2000,A11,'Recipe Ingredients'!$G$2:$G$2000,"Basket") | R11: =COUNTIFS('Recipe Ingredients'!$A$2:$A$2000,A11,'Recipe Ingredients'!$G$2:$G$2000,"Protein")+COUNTIFS('Recipe Ingredients'!$A$2:$A$2000,A11,'Recipe Ingredients'!$G$2:$G$2000,"Pantry") | S11: =IFERROR(Q11/(Q11+R11),0) | T11: =IF(S11>='Start Here'!$C$6,"Yes","No") | U11: Mango (Feb-May, Aug-Sep) | V11: 1. Cut all the fruit and cucumber into spears or chunks. 2. Pile into cups. 3. Squeeze lime over generously. 4. Dust with yaji and a pinch of salt just before eating. | W11: A strong candidate for a ready-to-eat snack box. | X11: Draft
A12: R025 | B12: Garden Egg Chopped Salad | C12: Salad | D12: Lunch / Side | E12: Shirazi / Israeli chopped salad | F12: Raw garden egg adds a crunchy, slightly bitter bite. | G12: Weight management, Wellness | H12: Vegan | I12: 15 | J12: 0 | K12: =I12+J12 | L12: =IF(J12=0,"No-cook",IF(K12<=25,"Quick","Standard")) | M12: 2 | N12: 140 | O12: 3 | P12: Garden egg, Tomato, Cucumber, Onion | Q12: =COUNTIFS('Recipe Ingredients'!$A$2:$A$2000,A12,'Recipe Ingredients'!$G$2:$G$2000,"Basket") | R12: =COUNTIFS('Recipe Ingredients'!$A$2:$A$2000,A12,'Recipe Ingredients'!$G$2:$G$2000,"Protein")+COUNTIFS('Recipe Ingredients'!$A$2:$A$2000,A12,'Recipe Ingredients'!$G$2:$G$2000,"Pantry") | S12: =IFERROR(Q12/(Q12+R12),0) | T12: =IF(S12>='Start Here'!$C$6,"Yes","No") | U12: Garden egg (Jan-Oct) | V12: 1. Dice garden eggs, tomatoes, cucumber and onion into small even pieces. 2. Chop the parsley. 3. Dress with lemon juice, olive oil and salt. 4. Rest 5 minutes before serving. | W12: Scent leaf instead of parsley gives it a distinctly Nigerian finish. | X12: Draft
A13: R026 | B13: Grilled Pineapple & Chicken Salad | C13: Salad | D13: Lunch / Dinner | E13: Hawaiian grilled chicken salad | F13: Yaji-rubbed chicken and local lettuce. | G13: Training, Weight management | H13: Contains meat | I13: 15 | J13: 15 | K13: =I13+J13 | L13: =IF(J13=0,"No-cook",IF(K13<=25,"Quick","Standard")) | M13: 2 | N13: 420 | O13: 35 | P13: Pineapple, Lettuce, Cucumber, Red bell pepper | Q13: =COUNTIFS('Recipe Ingredients'!$A$2:$A$2000,A13,'Recipe Ingredients'!$G$2:$G$2000,"Basket") | R13: =COUNTIFS('Recipe Ingredients'!$A$2:$A$2000,A13,'Recipe Ingredients'!$G$2:$G$2000,"Protein")+COUNTIFS('Recipe Ingredients'!$A$2:$A$2000,A13,'Recipe Ingredients'!$G$2:$G$2000,"Pantry") | S13: =IFERROR(Q13/(Q13+R13),0) | T13: =IF(S13>='Start Here'!$C$6,"Yes","No") | U13: Year-round | V13: 1. Rub chicken with yaji, oil and salt. Grill or pan-fry 6 minutes a side. 2. Grill pineapple rings until charred. 3. Whisk lime juice, honey and oil into a dressing. 4. Toss lettuce, cucumber, tatashe and spring onion with dressing. Top with sliced chicken and pineapple. | X13: Draft
A14: R027 | B14: Avocado, Mango & Cucumber Salad | C14: Salad | D14: Lunch / Side | E14: Mexican mango and avocado salad | F14: Ata rodo for heat, coriander for freshness. | G14: Wellness, Plant-based | H14: Vegan | I14: 15 | J14: 0 | K14: =I14+J14 | L14: =IF(J14=0,"No-cook",IF(K14<=25,"Quick","Standard")) | M14: 2 | N14: 260 | O14: 3 | P14: Avocado, Mango, Cucumber, Onion | Q14: =COUNTIFS('Recipe Ingredients'!$A$2:$A$2000,A14,'Recipe Ingredients'!$G$2:$G$2000,"Basket") | R14: =COUNTIFS('Recipe Ingredients'!$A$2:$A$2000,A14,'Recipe Ingredients'!$G$2:$G$2000,"Protein")+COUNTIFS('Recipe Ingredients'!$A$2:$A$2000,A14,'Recipe Ingredients'!$G$2:$G$2000,"Pantry") | S14: =IFERROR(Q14/(Q14+R14),0) | T14: =IF(S14>='Start Here'!$C$6,"Yes","No") | U14: Mango (Feb-May, Aug-Sep) | V14: 1. Cube avocado, mango and cucumber. 2. Finely slice onion and ata rodo. 3. Toss with lime juice, olive oil and salt. 4. Scatter coriander over the top. | W14: Best Feb to May. Use pineapple off season. | X14: Draft
A15: R028 | B15: Watermelon, Cucumber & Grilled Wara Salad | C15: Salad | D15: Lunch / Side | E15: Watermelon and feta salad (Greece / Levant) | F15: Grilled wara (local soft cheese) replaces feta. | G15: Hydration, Wellness | H15: Vegetarian | I15: 15 | J15: 5 | K15: =I15+J15 | L15: =IF(J15=0,"No-cook",IF(K15<=25,"Quick","Standard")) | M15: 2 | N15: 230 | O15: 12 | P15: Watermelon, Cucumber, Onion, Mint | Q15: =COUNTIFS('Recipe Ingredients'!$A$2:$A$2000,A15,'Recipe Ingredients'!$G$2:$G$2000,"Basket") | R15: =COUNTIFS('Recipe Ingredients'!$A$2:$A$2000,A15,'Recipe Ingredients'!$G$2:$G$2000,"Protein")+COUNTIFS('Recipe Ingredients'!$A$2:$A$2000,A15,'Recipe Ingredients'!$G$2:$G$2000,"Pantry") | S15: =IFERROR(Q15/(Q15+R15),0) | T15: =IF(S15>='Start Here'!$C$6,"Yes","No") | U15: Year-round | V15: 1. Slice wara and sear in a hot pan until golden on both sides. 2. Cube watermelon and cucumber, thinly slice the onion. 3. Toss with lime juice, mint and olive oil. 4. Top with the warm wara and black pepper. | X15: Draft
A16: R029 | B16: Lighter Chicken Caesar | C16: Salad | D16: Lunch / Dinner | E16: Caesar salad (Tijuana, Mexico) | F16: Yoghurt, garlic and lemon dressing instead of a mayo-heavy one. | G16: Training, Weight management | H16: Contains meat | I16: 15 | J16: 15 | K16: =I16+J16 | L16: =IF(J16=0,"No-cook",IF(K16<=25,"Quick","Standard")) | M16: 2 | N16: 430 | O16: 38 | P16: Lettuce, Tomato, Lemon, Garlic | Q16: =COUNTIFS('Recipe Ingredients'!$A$2:$A$2000,A16,'Recipe Ingredients'!$G$2:$G$2000,"Basket") | R16: =COUNTIFS('Recipe Ingredients'!$A$2:$A$2000,A16,'Recipe Ingredients'!$G$2:$G$2000,"Protein")+COUNTIFS('Recipe Ingredients'!$A$2:$A$2000,A16,'Recipe Ingredients'!$G$2:$G$2000,"Pantry") | S16: =IFERROR(Q16/(Q16+R16),0) | T16: =IF(S16>='Start Here'!$C$6,"Yes","No") | U16: Year-round | V16: 1. Season and grill the chicken, then slice. 2. Whisk yoghurt, grated garlic, lemon juice, mustard and half the parmesan. 3. Tear lettuce and toss with tomatoes and dressing. 4. Top with chicken, croutons and the rest of the parmesan. | X16: Draft
A17: R030 | B17: Crunchy Groundnut Cabbage Slaw | C17: Salad | D17: Side / Lunch | E17: Thai / Asian slaw with peanut dressing | F17: Local groundnut paste and both cabbages. | G17: Plant-based, Weight management | H17: Vegan | I17: 20 | J17: 0 | K17: =I17+J17 | L17: =IF(J17=0,"No-cook",IF(K17<=25,"Quick","Standard")) | M17: 4 | N17: 210 | O17: 7 | P17: Cabbage, Purple cabbage, Carrot, Spring onion | Q17: =COUNTIFS('Recipe Ingredients'!$A$2:$A$2000,A17,'Recipe Ingredients'!$G$2:$G$2000,"Basket") | R17: =COUNTIFS('Recipe Ingredients'!$A$2:$A$2000,A17,'Recipe Ingredients'!$G$2:$G$2000,"Protein")+COUNTIFS('Recipe Ingredients'!$A$2:$A$2000,A17,'Recipe Ingredients'!$G$2:$G$2000,"Pantry") | S17: =IFERROR(Q17/(Q17+R17),0) | T17: =IF(S17>='Start Here'!$C$6,"Yes","No") | U17: Year-round | V17: 1. Finely shred both cabbages and julienne the carrots. 2. Whisk groundnut paste, lime juice, grated ginger, soy and honey with a splash of water. 3. Toss vegetables with dressing. 4. Top with spring onion, coriander and roasted groundnuts. | W17: Holds well for 2 days, so it is a good meal-prep side. | X17: Draft
A18: R031 | B18: Greek Salad with Wara | C18: Salad | D18: Lunch / Side | E18: Horiatiki (Greece) | F18: Wara replaces feta, local green pepper stays. | G18: Weight management, Wellness | H18: Vegetarian | I18: 15 | J18: 0 | K18: =I18+J18 | L18: =IF(J18=0,"No-cook",IF(K18<=25,"Quick","Standard")) | M18: 2 | N18: 280 | O18: 12 | P18: Tomato, Cucumber, Green / yellow bell pepper, Onion | Q18: =COUNTIFS('Recipe Ingredients'!$A$2:$A$2000,A18,'Recipe Ingredients'!$G$2:$G$2000,"Basket") | R18: =COUNTIFS('Recipe Ingredients'!$A$2:$A$2000,A18,'Recipe Ingredients'!$G$2:$G$2000,"Protein")+COUNTIFS('Recipe Ingredients'!$A$2:$A$2000,A18,'Recipe Ingredients'!$G$2:$G$2000,"Pantry") | S18: =IFERROR(Q18/(Q18+R18),0) | T18: =IF(S18>='Start Here'!$C$6,"Yes","No") | U18: Year-round | V18: 1. Cut tomatoes and cucumber into chunks. 2. Slice green pepper and onion into rings. 3. Add olives and cubes of wara. 4. Dress with olive oil, lemon and oregano. | X18: Draft
